Workbook

Sheet Datos
A1: Random Forest auditable · datos
A2: La partición fue fijada en Python. La columna y convierte la respuesta en 0/1; las cinco variables alimentan los siete árboles.
A3: id_cliente | B3: particion | C3: acepta_deposito | D3: y | E3: edad | F3: contactos_campana | G3: contactos_previos | H3: contacto_celular | I3: resultado_previo_exitoso
A4: CLI000001 | B4: Entrenamiento | C4: No | D4: =--(C4="Sí") | E4: 43 | F4: 3 | G4: 0 | H4: 1 | I4: 0
A5: CLI000002 | B5: Entrenamiento | C5: No | D5: =--(C5="Sí") | E5: 38 | F5: 1 | G5: 0 | H5: 1 | I5: 0
A6: CLI000003 | B6: Entrenamiento | C6: No | D6: =--(C6="Sí") | E6: 44 | F6: 2 | G6: 0 | H6: 0 | I6: 0
A7: CLI000004 | B7: Prueba | C7: No | D7: =--(C7="Sí") | E7: 49 | F7: 1 | G7: 0 | H7: 1 | I7: 0
A8: CLI000006 | B8: Entrenamiento | C8: No | D8: =--(C8="Sí") | E8: 46 | F8: 5 | G8: 1 | H8: 1 | I8: 1
A9: CLI000007 | B9: Entrenamiento | C9: No | D9: =--(C9="Sí") | E9: 38 | F9: 2 | G9: 0 | H9: 1 | I9: 0
A10: CLI000008 | B10: Prueba | C10: No | D10: =--(C10="Sí") | E10: 47 | F10: 2 | G10: 0 | H10: 1 | I10: 0
A11: CLI000009 | B11: Entrenamiento | C11: No | D11: =--(C11="Sí") | E11: 28 | F11: 5 | G11: 0 | H11: 0 | I11: 0
A12: CLI000011 | B12: Entrenamiento | C12: No | D12: =--(C12="Sí") | E12: 30 | F12: 1 | G12: 0 | H12: 1 | I12: 0
A13: CLI000012 | B13: Prueba | C13: No | D13: =--(C13="Sí") | E13: 26 | F13: 9 | G13: 1 | H13: 1 | I13: 0
A14: CLI000013 | B14: Entrenamiento | C14: No | D14: =--(C14="Sí") | E14: 45 | F14: 1 | G14: 0 | H14: 1 | I14: 0
A15: CLI000014 | B15: Entrenamiento | C15: No | D15: =--(C15="Sí") | E15: 28 | F15: 2 | G15: 0 | H15: 0 | I15: 0
... A6943: CLI008000 | B6943: Prueba | C6943: No | D6943: =--(C6943="Sí") | E6943: 57 | F6943: 15 | G6943: 0 | H6943: 1 | I6943: 0

Sheet Bosque
A1: Siete árboles en una sola tabla
A2: Cada fila es un nodo. Gini y reducción Gini son fórmulas; las probabilidades de hoja son la proporción ponderada de clase 1.
A3: Árbol | B3: Nodo | C3: ¿Hoja? | D3: Variable | E3: Umbral | F3: Hijo izq. | G3: Hijo der. | H3: N ponderado | I3: Clase 0 | J3: Clase 1 | K3: Gini | L3: Reducción Gini | M3: Prob. hoja
A4: 1 | B4: 0 | C4: No | D4: contactos_previos | E4: 0.5 | F4: 1 | G4: 4 | H4: 5220 | I4: 4620 | J4: 600 | K4: =IF(H4=0,0,1-(I4/H4)^2-(J4/H4)^2) | L4: =K4-(H5/H4)*K5-(H8/H4)*K8
A5: 1 | B5: 1 | C5: No | D5: contacto_celular | E5: 0.5 | F5: 2 | G5: 3 | H5: 4531 | I5: 4120 | J5: 411 | K5: =IF(H5=0,0,1-(I5/H5)^2-(J5/H5)^2) | L5: =K5-(H6/H5)*K6-(H7/H5)*K7
A6: 1 | B6: 2 | C6: Sí | D6: Hoja | H6: 1880 | I6: 1791 | J6: 89 | K6: =IF(H6=0,0,1-(I6/H6)^2-(J6/H6)^2) | L6: 0 | M6: =IF(H6=0,0,J6/H6)
A7: 1 | B7: 3 | C7: Sí | D7: Hoja | H7: 2651 | I7: 2329 | J7: 322 | K7: =IF(H7=0,0,1-(I7/H7)^2-(J7/H7)^2) | L7: 0 | M7: =IF(H7=0,0,J7/H7)
A8: 1 | B8: 4 | C8: No | D8: contactos_previos | E8: 1.5 | F8: 5 | G8: 6 | H8: 689 | I8: 500 | J8: 189 | K8: =IF(H8=0,0,1-(I8/H8)^2-(J8/H8)^2) | L8: =K8-(H9/H8)*K9-(H10/H8)*K10
A9: 1 | B9: 5 | C9: Sí | D9: Hoja | H9: 552 | I9: 425 | J9: 127 | K9: =IF(H9=0,0,1-(I9/H9)^2-(J9/H9)^2) | L9: 0 | M9: =IF(H9=0,0,J9/H9)
A10: 1 | B10: 6 | C10: Sí | D10: Hoja | H10: 137 | I10: 75 | J10: 62 | K10: =IF(H10=0,0,1-(I10/H10)^2-(J10/H10)^2) | L10: 0 | M10: =IF(H10=0,0,J10/H10)
A11: 2 | B11: 0 | C11: No | D11: contacto_celular | E11: 0.5 | F11: 1 | G11: 4 | H11: 5220 | I11: 4605 | J11: 615 | K11: =IF(H11=0,0,1-(I11/H11)^2-(J11/H11)^2) | L11: =K11-(H12/H11)*K12-(H15/H11)*K15
A12: 2 | B12: 1 | C12: No | D12: edad | E12: 58.5 | F12: 2 | G12: 3 | H12: 1873 | I12: 1772 | J12: 101 | K12: =IF(H12=0,0,1-(I12/H12)^2-(J12/H12)^2) | L12: =K12-(H13/H12)*K13-(H14/H12)*K14
A13: 2 | B13: 2 | C13: Sí | D13: Hoja | H13: 1810 | I13: 1718 | J13: 92 | K13: =IF(H13=0,0,1-(I13/H13)^2-(J13/H13)^2) | L13: 0 | M13: =IF(H13=0,0,J13/H13)
A14: 2 | B14: 3 | C14: Sí | D14: Hoja | H14: 63 | I14: 54 | J14: 9 | K14: =IF(H14=0,0,1-(I14/H14)^2-(J14/H14)^2) | L14: 0 | M14: =IF(H14=0,0,J14/H14)
A15: 2 | B15: 4 | C15: No | D15: resultado_previo_exitoso | E15: 0.5 | F15: 5 | G15: 6 | H15: 3347 | I15: 2833 | J15: 514 | K15: =IF(H15=0,0,1-(I15/H15)^2-(J15/H15)^2) | L15: =K15-(H16/H15)*K16-(H17/H15)*K17
A16: 2 | B16: 5 | C16: Sí | D16: Hoja | H16: 3186 | I16: 2783 | J16: 403 | K16: =IF(H16=0,0,1-(I16/H16)^2-(J16/H16)^2) | L16: 0 | M16: =IF(H16=0,0,J16/H16)
A17: 2 | B17: 6 | C17: Sí | D17: Hoja | H17: 161 | I17: 50 | J17: 111 | K17: =IF(H17=0,0,1-(I17/H17)^2-(J17/H17)^2) | L17: 0 | M17: =IF(H17=0,0,J17/H17)
A18: 3 | B18: 0 | C18: No | D18: edad | E18: 60.5 | F18: 1 | G18: 4 | H18: 5220 | I18: 4614 | J18: 606 | K18: =IF(H18=0,0,1-(I18/H18)^2-(J18/H18)^2) | L18: =K18-(H19/H18)*K19-(H22/H18)*K22
A19: 3 | B19: 1 | C19: No | D19: resultado_previo_exitoso | E19: 0.5 | F19: 2 | G19: 3 | H19: 5102 | I19: 4556 | J19: 546 | K19: =IF(H19=0,0,1-(I19/H19)^2-(J19/H19)^2) | L19: =K19-(H20/H19)*K20-(H21/H19)*K21
A20: 3 | B20: 2 | C20: Sí | D20: Hoja | H20: 4959 | I20: 4508 | J20: 451 | K20: =IF(H20=0,0,1-(I20/H20)^2-(J20/H20)^2) | L20: 0 | M20: =IF(H20=0,0,J20/H20)
A21: 3 | B21: 3 | C21: Sí | D21: Hoja | H21: 143 | I21: 48 | J21: 95 | K21: =IF(H21=0,0,1-(I21/H21)^2-(J21/H21)^2) | L21: 0 | M21: =IF(H21=0,0,J21/H21)
A22: 3 | B22: 4 | C22: Sí | D22: Hoja | H22: 118 | I22: 58 | J22: 60 | K22: =IF(H22=0,0,1-(I22/H22)^2-(J22/H22)^2) | L22: 0 | M22: =IF(H22=0,0,J22/H22)
A23: 4 | B23: 0 | C23: No | D23: edad | E23: 59.5 | F23: 1 | G23: 4 | H23: 5220 | I23: 4647 | J23: 573 | K23: =IF(H23=0,0,1-(I23/H23)^2-(J23/H23)^2) | L23: =K23-(H24/H23)*K24-(H27/H23)*K27
A24: 4 | B24: 1 | C24: No | D24: edad | E24: 24.5 | F24: 2 | G24: 3 | H24: 5047 | I24: 4547 | J24: 500 | K24: =IF(H24=0,0,1-(I24/H24)^2-(J24/H24)^2) | L24: =K24-(H25/H24)*K25-(H26/H24)*K26
A25: 4 | B25: 2 | C25: Sí | D25: Hoja | H25: 144 | I25: 96 | J25: 48 | K25: =IF(H25=0,0,1-(I25/H25)^2-(J25/H25)^2) | L25: 0 | M25: =IF(H25=0,0,J25/H25)
A26: 4 | B26: 3 | C26: Sí | D26: Hoja | H26: 4903 | I26: 4451 | J26: 452 | K26: =IF(H26=0,0,1-(I26/H26)^2-(J26/H26)^2) | L26: 0 | M26: =IF(H26=0,0,J26/H26)
A27: 4 | B27: 4 | C27: No | D27: edad | E27: 67.5 | F27: 5 | G27: 6 | H27: 173 | I27: 100 | J27: 73 | K27: =IF(H27=0,0,1-(I27/H27)^2-(J27/H27)^2) | L27: =K27-(H28/H27)*K28-(H29/H27)*K29
A28: 4 | B28: 5 | C28: Sí | D28: Hoja | H28: 101 | I28: 66 | J28: 35 | K28: =IF(H28=0,0,1-(I28/H28)^2-(J28/H28)^2) | L28: 0 | M28: =IF(H28=0,0,J28/H28)
A29: 4 | B29: 6 | C29: Sí | D29: Hoja | H29: 72 | I29: 34 | J29: 38 | K29: =IF(H29=0,0,1-(I29/H29)^2-(J29/H29)^2) | L29: 0 | M29: =IF(H29=0,0,J29/H29)
A30: 5 | B30: 0 | C30: No | D30: contactos_previos | E30: 1.5 | F30: 1 | G30: 4 | H30: 5220 | I30: 4635 | J30: 585 | K30: =IF(H30=0,0,1-(I30/H30)^2-(J30/H30)^2) | L30: =K30-(H31/H30)*K31-(H34/H30)*K34
A31: 5 | B31: 1 | C31: No | D31: edad | E31: 60.5 | F31: 2 | G31: 3 | H31: 5089 | I31: 4567 | J31: 522 | K31: =IF(H31=0,0,1-(I31/H31)^2-(J31/H31)^2) | L31: =K31-(H32/H31)*K32-(H33/H31)*K33
A32: 5 | B32: 2 | C32: Sí | D32: Hoja | H32: 4984 | I32: 4495 | J32: 489 | K32: =IF(H32=0,0,1-(I32/H32)^2-(J32/H32)^2) | L32: 0 | M32: =IF(H32=0,0,J32/H32)
A33: 5 | B33: 3 | C33: Sí | D33: Hoja | H33: 105 | I33: 72 | J33: 33 | K33: =IF(H33=0,0,1-(I33/H33)^2-(J33/H33)^2) | L33: 0 | M33: =IF(H33=0,0,J33/H33)
A34: 5 | B34: 4 | C34: No | D34: edad | E34: 36.5 | F34: 5 | G34: 6 | H34: 131 | I34: 68 | J34: 63 | K34: =IF(H34=0,0,1-(I34/H34)^2-(J34/H34)^2) | L34: =K34-(H35/H34)*K35-(H36/H34)*K36
A35: 5 | B35: 5 | C35: Sí | D35: Hoja | H35: 61 | I35: 34 | J35: 27 | K35: =IF(H35=0,0,1-(I35/H35)^2-(J35/H35)^2) | L35: 0 | M35: =IF(H35=0,0,J35/H35)
A36: 5 | B36: 6 | C36: Sí | D36: Hoja | H36: 70 | I36: 34 | J36: 36 | K36: =IF(H36=0,0,1-(I36/H36)^2-(J36/H36)^2) | L36: 0 | M36: =IF(H36=0,0,J36/H36)
A37: 6 | B37: 0 | C37: No | D37: resultado_previo_exitoso | E37: 0.5 | F37: 1 | G37: 4 | H37: 5220 | I37: 4630 | J37: 590 | K37: =IF(H37=0,0,1-(I37/H37)^2-(J37/H37)^2) | L37: =K37-(H38/H37)*K38-(H41/H37)*K41
A38: 6 | B38: 1 | C38: No | D38: contacto_celular | E38: 0.5 | F38: 2 | G38: 3 | H38: 5048 | I38: 4581 | J38: 467 | K38: =IF(H38=0,0,1-(I38/H38)^2-(J38/H38)^2) | L38: =K38-(H39/H38)*K39-(H40/H38)*K40
A39: 6 | B39: 2 | C39: Sí | D39: Hoja | H39: 1920 | I39: 1812 | J39: 108 | K39: =IF(H39=0,0,1-(I39/H39)^2-(J39/H39)^2) | L39: 0 | M39: =IF(H39=0,0,J39/H39)
A40: 6 | B40: 3 | C40: Sí | D40: Hoja | H40: 3128 | I40: 2769 | J40: 359 | K40: =IF(H40=0,0,1-(I40/H40)^2-(J40/H40)^2) | L40: 0 | M40: =IF(H40=0,0,J40/H40)
...

Sheet Resultados
A1: Predicción, decisión e importancia
A2: Cambie el punto de corte en M2. Las siete probabilidades se calculan recorriendo los nodos de Bosque; la importancia es la reducción Gini normalizada por árbol. | M2: 0.2 | N2: ← Punto de corte editable | U2: Variable | V2: 1 | W2: 2 | X2: 3 | Y2: 4 | Z2: 5 | AA2: 6 | AB2: 7 | AC2: Promedio
A3: id_cliente | B3: partición | C3: y real | D3: fila Datos | E3: Árbol 1 | F3: Árbol 2 | G3: Árbol 3 | H3: Árbol 4 | I3: Árbol 5 | J3: Árbol 6 | K3: Árbol 7 | L3: Prob. bosque | M3: Punto de corte | N3: Contactar | O3: TP | P3: FP | Q3: FN | R3: TN | S3: Acierto | T3: Valor esperado | U3: resultado_previo_exitoso | V3: =IFERROR(SUMIFS(Bosque!$L:$L,Bosque!$A:$A,V$2,Bosque!$D:$D,$U3)/SUMIFS(Bosque!$L:$L,Bosque!$A:$A,V$2),0) | W3: =IFERROR(SUMIFS(Bosque!$L:$L,Bosque!$A:$A,W$2,Bosque!$D:$D,$U3)/SUMIFS(Bosque!$L:$L,Bosque!$A:$A,W$2),0) | X3: =IFERROR(SUMIFS(Bosque!$L:$L,Bosque!$A:$A,X$2,Bosque!$D:$D,$U3)/SUMIFS(Bosque!$L:$L,Bosque!$A:$A,X$2),0) | Y3: =IFERROR(SUMIFS(Bosque!$L:$L,Bosque!$A:$A,Y$2,Bosque!$D:$D,$U3)/SUMIFS(Bosque!$L:$L,Bosque!$A:$A,Y$2),0) | Z3: =IFERROR(SUMIFS(Bosque!$L:$L,Bosque!$A:$A,Z$2,Bosque!$D:$D,$U3)/SUMIFS(Bosque!$L:$L,Bosque!$A:$A,Z$2),0) | AA3: =IFERROR(SUMIFS(Bosque!$L:$L,Bosque!$A:$A,AA$2,Bosque!$D:$D,$U3)/SUMIFS(Bosque!$L:$L,Bosque!$A:$A,AA$2),0) | AB3: =IFERROR(SUMIFS(Bosque!$L:$L,Bosque!$A:$A,AB$2,Bosque!$D:$D,$U3)/SUMIFS(Bosque!$L:$L,Bosque!$A:$A,AB$2),0) | AC3: =AVERAGE(V3:AB3)
A4: =Datos!A4 | B4: =Datos!B4 | C4: =Datos!D4 | D4: 4 | E4: =IF(Datos!$G$4<=Bosque!$E$4,IF(Datos!$H$4<=Bosque!$E$5,Bosque!$M$6,Bosque!$M$7),IF(Datos!$G$4<=Bosque!$E$8,Bosque!$M$9,Bosque!$M$10)) | F4: =IF(Datos!$H$4<=Bosque!$E$11,IF(Datos!$E$4<=Bosque!$E$12,Bosque!$M$13,Bosque!$M$14),IF(Datos!$I$4<=Bosque!$E$15,Bosque!$M$16,Bosque!$M$17)) | G4: =IF(Datos!$E$4<=Bosque!$E$18,IF(Datos!$I$4<=Bosque!$E$19,Bosque!$M$20,Bosque!$M$21),Bosque!$M$22) | H4: =IF(Datos!$E$4<=Bosque!$E$23,IF(Datos!$E$4<=Bosque!$E$24,Bosque!$M$25,Bosque!$M$26),IF(Datos!$E$4<=Bosque!$E$27,Bosque!$M$28,Bosque!$M$29)) | I4: =IF(Datos!$G$4<=Bosque!$E$30,IF(Datos!$E$4<=Bosque!$E$31,Bosque!$M$32,Bosque!$M$33),IF(Datos!$E$4<=Bosque!$E$34,Bosque!$M$35,Bosque!$M$36)) | J4: =IF(Datos!$I$4<=Bosque!$E$37,IF(Datos!$H$4<=Bosque!$E$38,Bosque!$M$39,Bosque!$M$40),IF(Datos!$F$4<=Bosque!$E$41,Bosque!$M$42,Bosque!$M$43)) | K4: =IF(Datos!$G$4<=Bosque!$E$44,IF(Datos!$H$4<=Bosque!$E$45,Bosque!$M$46,Bosque!$M$47),IF(Datos!$F$4<=Bosque!$E$48,Bosque!$M$49,Bosque!$M$50)) | L4: =AVERAGE(E4:K4) | M4: =$M$2 | N4: =IF(L4>=M4,"Sí","No") | O4: =--AND(C4=1,N4="Sí") | P4: =--AND(C4=0,N4="Sí") | Q4: =--AND(C4=1,N4="No") | R4: =--AND(C4=0,N4="No") | S4: =--(C4=--(L4>=M4)) | T4: =O4*60000-P4*3000 | U4: contactos_previos | V4: =IFERROR(SUMIFS(Bosque!$L:$L,Bosque!$A:$A,V$2,Bosque!$D:$D,$U4)/SUMIFS(Bosque!$L:$L,Bosque!$A:$A,V$2),0) | W4: =IFERROR(SUMIFS(Bosque!$L:$L,Bosque!$A:$A,W$2,Bosque!$D:$D,$U4)/SUMIFS(Bosque!$L:$L,Bosque!$A:$A,W$2),0) | X4: =IFERROR(SUMIFS(Bosque!$L:$L,Bosque!$A:$A,X$2,Bosque!$D:$D,$U4)/SUMIFS(Bosque!$L:$L,Bosque!$A:$A,X$2),0) | Y4: =IFERROR(SUMIFS(Bosque!$L:$L,Bosque!$A:$A,Y$2,Bosque!$D:$D,$U4)/SUMIFS(Bosque!$L:$L,Bosque!$A:$A,Y$2),0) | Z4: =IFERROR(SUMIFS(Bosque!$L:$L,Bosque!$A:$A,Z$2,Bosque!$D:$D,$U4)/SUMIFS(Bosque!$L:$L,Bosque!$A:$A,Z$2),0) | AA4: =IFERROR(SUMIFS(Bosque!$L:$L,Bosque!$A:$A,AA$2,Bosque!$D:$D,$U4)/SUMIFS(Bosque!$L:$L,Bosque!$A:$A,AA$2),0) | AB4: =IFERROR(SUMIFS(Bosque!$L:$L,Bosque!$A:$A,AB$2,Bosque!$D:$D,$U4)/SUMIFS(Bosque!$L:$L,Bosque!$A:$A,AB$2),0) | AC4: =AVERAGE(V4:AB4)
A5: =Datos!A5 | B5: =Datos!B5 | C5: =Datos!D5 | D5: 5 | E5: =IF(Datos!$G$5<=Bosque!$E$4,IF(Datos!$H$5<=Bosque!$E$5,Bosque!$M$6,Bosque!$M$7),IF(Datos!$G$5<=Bosque!$E$8,Bosque!$M$9,Bosque!$M$10)) | F5: =IF(Datos!$H$5<=Bosque!$E$11,IF(Datos!$E$5<=Bosque!$E$12,Bosque!$M$13,Bosque!$M$14),IF(Datos!$I$5<=Bosque!$E$15,Bosque!$M$16,Bosque!$M$17)) | G5: =IF(Datos!$E$5<=Bosque!$E$18,IF(Datos!$I$5<=Bosque!$E$19,Bosque!$M$20,Bosque!$M$21),Bosque!$M$22) | H5: =IF(Datos!$E$5<=Bosque!$E$23,IF(Datos!$E$5<=Bosque!$E$24,Bosque!$M$25,Bosque!$M$26),IF(Datos!$E$5<=Bosque!$E$27,Bosque!$M$28,Bosque!$M$29)) | I5: =IF(Datos!$G$5<=Bosque!$E$30,IF(Datos!$E$5<=Bosque!$E$31,Bosque!$M$32,Bosque!$M$33),IF(Datos!$E$5<=Bosque!$E$34,Bosque!$M$35,Bosque!$M$36)) | J5: =IF(Datos!$I$5<=Bosque!$E$37,IF(Datos!$H$5<=Bosque!$E$38,Bosque!$M$39,Bosque!$M$40),IF(Datos!$F$5<=Bosque!$E$41,Bosque!$M$42,Bosque!$M$43)) | K5: =IF(Datos!$G$5<=Bosque!$E$44,IF(Datos!$H$5<=Bosque!$E$45,Bosque!$M$46,Bosque!$M$47),IF(Datos!$F$5<=Bosque!$E$48,Bosque!$M$49,Bosque!$M$50)) | L5: =AVERAGE(E5:K5) | M5: =$M$2 | N5: =IF(L5>=M5,"Sí","No") | O5: =--AND(C5=1,N5="Sí") | P5: =--AND(C5=0,N5="Sí") | Q5: =--AND(C5=1,N5="No") | R5: =--AND(C5=0,N5="No") | S5: =--(C5=--(L5>=M5)) | T5: =O5*60000-P5*3000 | U5: edad | V5: =IFERROR(SUMIFS(Bosque!$L:$L,Bosque!$A:$A,V$2,Bosque!$D:$D,$U5)/SUMIFS(Bosque!$L:$L,Bosque!$A:$A,V$2),0) | W5: =IFERROR(SUMIFS(Bosque!$L:$L,Bosque!$A:$A,W$2,Bosque!$D:$D,$U5)/SUMIFS(Bosque!$L:$L,Bosque!$A:$A,W$2),0) | X5: =IFERROR(SUMIFS(Bosque!$L:$L,Bosque!$A:$A,X$2,Bosque!$D:$D,$U5)/SUMIFS(Bosque!$L:$L,Bosque!$A:$A,X$2),0) | Y5: =IFERROR(SUMIFS(Bosque!$L:$L,Bosque!$A:$A,Y$2,Bosque!$D:$D,$U5)/SUMIFS(Bosque!$L:$L,Bosque!$A:$A,Y$2),0) | Z5: =IFERROR(SUMIFS(Bosque!$L:$L,Bosque!$A:$A,Z$2,Bosque!$D:$D,$U5)/SUMIFS(Bosque!$L:$L,Bosque!$A:$A,Z$2),0) | AA5: =IFERROR(SUMIFS(Bosque!$L:$L,Bosque!$A:$A,AA$2,Bosque!$D:$D,$U5)/SUMIFS(Bosque!$L:$L,Bosque!$A:$A,AA$2),0) | AB5: =IFERROR(SUMIFS(Bosque!$L:$L,Bosque!$A:$A,AB$2,Bosque!$D:$D,$U5)/SUMIFS(Bosque!$L:$L,Bosque!$A:$A,AB$2),0) | AC5: =AVERAGE(V5:AB5)
A6: =Datos!A6 | B6: =Datos!B6 | C6: =Datos!D6 | D6: 6 | E6: =IF(Datos!$G$6<=Bosque!$E$4,IF(Datos!$H$6<=Bosque!$E$5,Bosque!$M$6,Bosque!$M$7),IF(Datos!$G$6<=Bosque!$E$8,Bosque!$M$9,Bosque!$M$10)) | F6: =IF(Datos!$H$6<=Bosque!$E$11,IF(Datos!$E$6<=Bosque!$E$12,Bosque!$M$13,Bosque!$M$14),IF(Datos!$I$6<=Bosque!$E$15,Bosque!$M$16,Bosque!$M$17)) | G6: =IF(Datos!$E$6<=Bosque!$E$18,IF(Datos!$I$6<=Bosque!$E$19,Bosque!$M$20,Bosque!$M$21),Bosque!$M$22) | H6: =IF(Datos!$E$6<=Bosque!$E$23,IF(Datos!$E$6<=Bosque!$E$24,Bosque!$M$25,Bosque!$M$26),IF(Datos!$E$6<=Bosque!$E$27,Bosque!$M$28,Bosque!$M$29)) | I6: =IF(Datos!$G$6<=Bosque!$E$30,IF(Datos!$E$6<=Bosque!$E$31,Bosque!$M$32,Bosque!$M$33),IF(Datos!$E$6<=Bosque!$E$34,Bosque!$M$35,Bosque!$M$36)) | J6: =IF(Datos!$I$6<=Bosque!$E$37,IF(Datos!$H$6<=Bosque!$E$38,Bosque!$M$39,Bosque!$M$40),IF(Datos!$F$6<=Bosque!$E$41,Bosque!$M$42,Bosque!$M$43)) | K6: =IF(Datos!$G$6<=Bosque!$E$44,IF(Datos!$H$6<=Bosque!$E$45,Bosque!$M$46,Bosque!$M$47),IF(Datos!$F$6<=Bosque!$E$48,Bosque!$M$49,Bosque!$M$50)) | L6: =AVERAGE(E6:K6) | M6: =$M$2 | N6: =IF(L6>=M6,"Sí","No") | O6: =--AND(C6=1,N6="Sí") | P6: =--AND(C6=0,N6="Sí") | Q6: =--AND(C6=1,N6="No") | R6: =--AND(C6=0,N6="No") | S6: =--(C6=--(L6>=M6)) | T6: =O6*60000-P6*3000 | U6: contacto_celular | V6: =IFERROR(SUMIFS(Bosque!$L:$L,Bosque!$A:$A,V$2,Bosque!$D:$D,$U6)/SUMIFS(Bosque!$L:$L,Bosque!$A:$A,V$2),0) | W6: =IFERROR(SUMIFS(Bosque!$L:$L,Bosque!$A:$A,W$2,Bosque!$D:$D,$U6)/SUMIFS(Bosque!$L:$L,Bosque!$A:$A,W$2),0) | X6: =IFERROR(SUMIFS(Bosque!$L:$L,Bosque!$A:$A,X$2,Bosque!$D:$D,$U6)/SUMIFS(Bosque!$L:$L,Bosque!$A:$A,X$2),0) | Y6: =IFERROR(SUMIFS(Bosque!$L:$L,Bosque!$A:$A,Y$2,Bosque!$D:$D,$U6)/SUMIFS(Bosque!$L:$L,Bosque!$A:$A,Y$2),0) | Z6: =IFERROR(SUMIFS(Bosque!$L:$L,Bosque!$A:$A,Z$2,Bosque!$D:$D,$U6)/SUMIFS(Bosque!$L:$L,Bosque!$A:$A,Z$2),0) | AA6: =IFERROR(SUMIFS(Bosque!$L:$L,Bosque!$A:$A,AA$2,Bosque!$D:$D,$U6)/SUMIFS(Bosque!$L:$L,Bosque!$A:$A,AA$2),0) | AB6: =IFERROR(SUMIFS(Bosque!$L:$L,Bosque!$A:$A,AB$2,Bosque!$D:$D,$U6)/SUMIFS(Bosque!$L:$L,Bosque!$A:$A,AB$2),0) | AC6: =AVERAGE(V6:AB6)
A7: =Datos!A7 | B7: =Datos!B7 | C7: =Datos!D7 | D7: 7 | E7: =IF(Datos!$G$7<=Bosque!$E$4,IF(Datos!$H$7<=Bosque!$E$5,Bosque!$M$6,Bosque!$M$7),IF(Datos!$G$7<=Bosque!$E$8,Bosque!$M$9,Bosque!$M$10)) | F7: =IF(Datos!$H$7<=Bosque!$E$11,IF(Datos!$E$7<=Bosque!$E$12,Bosque!$M$13,Bosque!$M$14),IF(Datos!$I$7<=Bosque!$E$15,Bosque!$M$16,Bosque!$M$17)) | G7: =IF(Datos!$E$7<=Bosque!$E$18,IF(Datos!$I$7<=Bosque!$E$19,Bosque!$M$20,Bosque!$M$21),Bosque!$M$22) | H7: =IF(Datos!$E$7<=Bosque!$E$23,IF(Datos!$E$7<=Bosque!$E$24,Bosque!$M$25,Bosque!$M$26),IF(Datos!$E$7<=Bosque!$E$27,Bosque!$M$28,Bosque!$M$29)) | I7: =IF(Datos!$G$7<=Bosque!$E$30,IF(Datos!$E$7<=Bosque!$E$31,Bosque!$M$32,Bosque!$M$33),IF(Datos!$E$7<=Bosque!$E$34,Bosque!$M$35,Bosque!$M$36)) | J7: =IF(Datos!$I$7<=Bosque!$E$37,IF(Datos!$H$7<=Bosque!$E$38,Bosque!$M$39,Bosque!$M$40),IF(Datos!$F$7<=Bosque!$E$41,Bosque!$M$42,Bosque!$M$43)) | K7: =IF(Datos!$G$7<=Bosque!$E$44,IF(Datos!$H$7<=Bosque!$E$45,Bosque!$M$46,Bosque!$M$47),IF(Datos!$F$7<=Bosque!$E$48,Bosque!$M$49,Bosque!$M$50)) | L7: =AVERAGE(E7:K7) | M7: =$M$2 | N7: =IF(L7>=M7,"Sí","No") | O7: =--AND(C7=1,N7="Sí") | P7: =--AND(C7=0,N7="Sí") | Q7: =--AND(C7=1,N7="No") | R7: =--AND(C7=0,N7="No") | S7: =--(C7=--(L7>=M7)) | T7: =O7*60000-P7*3000 | U7: contactos_campana | V7: =IFERROR(SUMIFS(Bosque!$L:$L,Bosque!$A:$A,V$2,Bosque!$D:$D,$U7)/SUMIFS(Bosque!$L:$L,Bosque!$A:$A,V$2),0) | W7: =IFERROR(SUMIFS(Bosque!$L:$L,Bosque!$A:$A,W$2,Bosque!$D:$D,$U7)/SUMIFS(Bosque!$L:$L,Bosque!$A:$A,W$2),0) | X7: =IFERROR(SUMIFS(Bosque!$L:$L,Bosque!$A:$A,X$2,Bosque!$D:$D,$U7)/SUMIFS(Bosque!$L:$L,Bosque!$A:$A,X$2),0) | Y7: =IFERROR(SUMIFS(Bosque!$L:$L,Bosque!$A:$A,Y$2,Bosque!$D:$D,$U7)/SUMIFS(Bosque!$L:$L,Bosque!$A:$A,Y$2),0) | Z7: =IFERROR(SUMIFS(Bosque!$L:$L,Bosque!$A:$A,Z$2,Bosque!$D:$D,$U7)/SUMIFS(Bosque!$L:$L,Bosque!$A:$A,Z$2),0) | AA7: =IFERROR(SUMIFS(Bosque!$L:$L,Bosque!$A:$A,AA$2,Bosque!$D:$D,$U7)/SUMIFS(Bosque!$L:$L,Bosque!$A:$A,AA$2),0) | AB7: =IFERROR(SUMIFS(Bosque!$L:$L,Bosque!$A:$A,AB$2,Bosque!$D:$D,$U7)/SUMIFS(Bosque!$L:$L,Bosque!$A:$A,AB$2),0) | AC7: =AVERAGE(V7:AB7)
A8: =Datos!A8 | B8: =Datos!B8 | C8: =Datos!D8 | D8: 8 | E8: =IF(Datos!$G$8<=Bosque!$E$4,IF(Datos!$H$8<=Bosque!$E$5,Bosque!$M$6,Bosque!$M$7),IF(Datos!$G$8<=Bosque!$E$8,Bosque!$M$9,Bosque!$M$10)) | F8: =IF(Datos!$H$8<=Bosque!$E$11,IF(Datos!$E$8<=Bosque!$E$12,Bosque!$M$13,Bosque!$M$14),IF(Datos!$I$8<=Bosque!$E$15,Bosque!$M$16,Bosque!$M$17)) | G8: =IF(Datos!$E$8<=Bosque!$E$18,IF(Datos!$I$8<=Bosque!$E$19,Bosque!$M$20,Bosque!$M$21),Bosque!$M$22) | H8: =IF(Datos!$E$8<=Bosque!$E$23,IF(Datos!$E$8<=Bosque!$E$24,Bosque!$M$25,Bosque!$M$26),IF(Datos!$E$8<=Bosque!$E$27,Bosque!$M$28,Bosque!$M$29)) | I8: =IF(Datos!$G$8<=Bosque!$E$30,IF(Datos!$E$8<=Bosque!$E$31,Bosque!$M$32,Bosque!$M$33),IF(Datos!$E$8<=Bosque!$E$34,Bosque!$M$35,Bosque!$M$36)) | J8: =IF(Datos!$I$8<=Bosque!$E$37,IF(Datos!$H$8<=Bosque!$E$38,Bosque!$M$39,Bosque!$M$40),IF(Datos!$F$8<=Bosque!$E$41,Bosque!$M$42,Bosque!$M$43)) | K8: =IF(Datos!$G$8<=Bosque!$E$44,IF(Datos!$H$8<=Bosque!$E$45,Bosque!$M$46,Bosque!$M$47),IF(Datos!$F$8<=Bosque!$E$48,Bosque!$M$49,Bosque!$M$50)) | L8: =AVERAGE(E8:K8) | M8: =$M$2 | N8: =IF(L8>=M8,"Sí","No") | O8: =--AND(C8=1,N8="Sí") | P8: =--AND(C8=0,N8="Sí") | Q8: =--AND(C8=1,N8="No") | R8: =--AND(C8=0,N8="No") | S8: =--(C8=--(L8>=M8)) | T8: =O8*60000-P8*3000
A9: =Datos!A9 | B9: =Datos!B9 | C9: =Datos!D9 | D9: 9 | E9: =IF(Datos!$G$9<=Bosque!$E$4,IF(Datos!$H$9<=Bosque!$E$5,Bosque!$M$6,Bosque!$M$7),IF(Datos!$G$9<=Bosque!$E$8,Bosque!$M$9,Bosque!$M$10)) | F9: =IF(Datos!$H$9<=Bosque!$E$11,IF(Datos!$E$9<=Bosque!$E$12,Bosque!$M$13,Bosque!$M$14),IF(Datos!$I$9<=Bosque!$E$15,Bosque!$M$16,Bosque!$M$17)) | G9: =IF(Datos!$E$9<=Bosque!$E$18,IF(Datos!$I$9<=Bosque!$E$19,Bosque!$M$20,Bosque!$M$21),Bosque!$M$22) | H9: =IF(Datos!$E$9<=Bosque!$E$23,IF(Datos!$E$9<=Bosque!$E$24,Bosque!$M$25,Bosque!$M$26),IF(Datos!$E$9<=Bosque!$E$27,Bosque!$M$28,Bosque!$M$29)) | I9: =IF(Datos!$G$9<=Bosque!$E$30,IF(Datos!$E$9<=Bosque!$E$31,Bosque!$M$32,Bosque!$M$33),IF(Datos!$E$9<=Bosque!$E$34,Bosque!$M$35,Bosque!$M$36)) | J9: =IF(Datos!$I$9<=Bosque!$E$37,IF(Datos!$H$9<=Bosque!$E$38,Bosque!$M$39,Bosque!$M$40),IF(Datos!$F$9<=Bosque!$E$41,Bosque!$M$42,Bosque!$M$43)) | K9: =IF(Datos!$G$9<=Bosque!$E$44,IF(Datos!$H$9<=Bosque!$E$45,Bosque!$M$46,Bosque!$M$47),IF(Datos!$F$9<=Bosque!$E$48,Bosque!$M$49,Bosque!$M$50)) | L9: =AVERAGE(E9:K9) | M9: =$M$2 | N9: =IF(L9>=M9,"Sí","No") | O9: =--AND(C9=1,N9="Sí") | P9: =--AND(C9=0,N9="Sí") | Q9: =--AND(C9=1,N9="No") | R9: =--AND(C9=0,N9="No") | S9: =--(C9=--(L9>=M9)) | T9: =O9*60000-P9*3000
A10: =Datos!A10 | B10: =Datos!B10 | C10: =Datos!D10 | D10: 10 | E10: =IF(Datos!$G$10<=Bosque!$E$4,IF(Datos!$H$10<=Bosque!$E$5,Bosque!$M$6,Bosque!$M$7),IF(Datos!$G$10<=Bosque!$E$8,Bosque!$M$9,Bosque!$M$10)) | F10: =IF(Datos!$H$10<=Bosque!$E$11,IF(Datos!$E$10<=Bosque!$E$12,Bosque!$M$13,Bosque!$M$14),IF(Datos!$I$10<=Bosque!$E$15,Bosque!$M$16,Bosque!$M$17)) | G10: =IF(Datos!$E$10<=Bosque!$E$18,IF(Datos!$I$10<=Bosque!$E$19,Bosque!$M$20,Bosque!$M$21),Bosque!$M$22) | H10: =IF(Datos!$E$10<=Bosque!$E$23,IF(Datos!$E$10<=Bosque!$E$24,Bosque!$M$25,Bosque!$M$26),IF(Datos!$E$10<=Bosque!$E$27,Bosque!$M$28,Bosque!$M$29)) | I10: =IF(Datos!$G$10<=Bosque!$E$30,IF(Datos!$E$10<=Bosque!$E$31,Bosque!$M$32,Bosque!$M$33),IF(Datos!$E$10<=Bosque!$E$34,Bosque!$M$35,Bosque!$M$36)) | J10: =IF(Datos!$I$10<=Bosque!$E$37,IF(Datos!$H$10<=Bosque!$E$38,Bosque!$M$39,Bosque!$M$40),IF(Datos!$F$10<=Bosque!$E$41,Bosque!$M$42,Bosque!$M$43)) | K10: =IF(Datos!$G$10<=Bosque!$E$44,IF(Datos!$H$10<=Bosque!$E$45,Bosque!$M$46,Bosque!$M$47),IF(Datos!$F$10<=Bosque!$E$48,Bosque!$M$49,Bosque!$M$50)) | L10: =AVERAGE(E10:K10) | M10: =$M$2 | N10: =IF(L10>=M10,"Sí","No") | O10: =--AND(C10=1,N10="Sí") | P10: =--AND(C10=0,N10="Sí") | Q10: =--AND(C10=1,N10="No") | R10: =--AND(C10=0,N10="No") | S10: =--(C10=--(L10>=M10)) | T10: =O10*60000-P10*3000
A11: =Datos!A11 | B11: =Datos!B11 | C11: =Datos!D11 | D11: 11 | E11: =IF(Datos!$G$11<=Bosque!$E$4,IF(Datos!$H$11<=Bosque!$E$5,Bosque!$M$6,Bosque!$M$7),IF(Datos!$G$11<=Bosque!$E$8,Bosque!$M$9,Bosque!$M$10)) | F11: =IF(Datos!$H$11<=Bosque!$E$11,IF(Datos!$E$11<=Bosque!$E$12,Bosque!$M$13,Bosque!$M$14),IF(Datos!$I$11<=Bosque!$E$15,Bosque!$M$16,Bosque!$M$17)) | G11: =IF(Datos!$E$11<=Bosque!$E$18,IF(Datos!$I$11<=Bosque!$E$19,Bosque!$M$20,Bosque!$M$21),Bosque!$M$22) | H11: =IF(Datos!$E$11<=Bosque!$E$23,IF(Datos!$E$11<=Bosque!$E$24,Bosque!$M$25,Bosque!$M$26),IF(Datos!$E$11<=Bosque!$E$27,Bosque!$M$28,Bosque!$M$29)) | I11: =IF(Datos!$G$11<=Bosque!$E$30,IF(Datos!$E$11<=Bosque!$E$31,Bosque!$M$32,Bosque!$M$33),IF(Datos!$E$11<=Bosque!$E$34,Bosque!$M$35,Bosque!$M$36)) | J11: =IF(Datos!$I$11<=Bosque!$E$37,IF(Datos!$H$11<=Bosque!$E$38,Bosque!$M$39,Bosque!$M$40),IF(Datos!$F$11<=Bosque!$E$41,Bosque!$M$42,Bosque!$M$43)) | K11: =IF(Datos!$G$11<=Bosque!$E$44,IF(Datos!$H$11<=Bosque!$E$45,Bosque!$M$46,Bosque!$M$47),IF(Datos!$F$11<=Bosque!$E$48,Bosque!$M$49,Bosque!$M$50)) | L11: =AVERAGE(E11:K11) | M11: =$M$2 | N11: =IF(L11>=M11,"Sí","No") | O11: =--AND(C11=1,N11="Sí") | P11: =--AND(C11=0,N11="Sí") | Q11: =--AND(C11=1,N11="No") | R11: =--AND(C11=0,N11="No") | S11: =--(C11=--(L11>=M11)) | T11: =O11*60000-P11*3000
A12: =Datos!A12 | B12: =Datos!B12 | C12: =Datos!D12 | D12: 12 | E12: =IF(Datos!$G$12<=Bosque!$E$4,IF(Datos!$H$12<=Bosque!$E$5,Bosque!$M$6,Bosque!$M$7),IF(Datos!$G$12<=Bosque!$E$8,Bosque!$M$9,Bosque!$M$10)) | F12: =IF(Datos!$H$12<=Bosque!$E$11,IF(Datos!$E$12<=Bosque!$E$12,Bosque!$M$13,Bosque!$M$14),IF(Datos!$I$12<=Bosque!$E$15,Bosque!$M$16,Bosque!$M$17)) | G12: =IF(Datos!$E$12<=Bosque!$E$18,IF(Datos!$I$12<=Bosque!$E$19,Bosque!$M$20,Bosque!$M$21),Bosque!$M$22) | H12: =IF(Datos!$E$12<=Bosque!$E$23,IF(Datos!$E$12<=Bosque!$E$24,Bosque!$M$25,Bosque!$M$26),IF(Datos!$E$12<=Bosque!$E$27,Bosque!$M$28,Bosque!$M$29)) | I12: =IF(Datos!$G$12<=Bosque!$E$30,IF(Datos!$E$12<=Bosque!$E$31,Bosque!$M$32,Bosque!$M$33),IF(Datos!$E$12<=Bosque!$E$34,Bosque!$M$35,Bosque!$M$36)) | J12: =IF(Datos!$I$12<=Bosque!$E$37,IF(Datos!$H$12<=Bosque!$E$38,Bosque!$M$39,Bosque!$M$40),IF(Datos!$F$12<=Bosque!$E$41,Bosque!$M$42,Bosque!$M$43)) | K12: =IF(Datos!$G$12<=Bosque!$E$44,IF(Datos!$H$12<=Bosque!$E$45,Bosque!$M$46,Bosque!$M$47),IF(Datos!$F$12<=Bosque!$E$48,Bosque!$M$49,Bosque!$M$50)) | L12: =AVERAGE(E12:K12) | M12: =$M$2 | N12: =IF(L12>=M12,"Sí","No") | O12: =--AND(C12=1,N12="Sí") | P12: =--AND(C12=0,N12="Sí") | Q12: =--AND(C12=1,N12="No") | R12: =--AND(C12=0,N12="No") | S12: =--(C12=--(L12>=M12)) | T12: =O12*60000-P12*3000
A13: =Datos!A13 | B13: =Datos!B13 | C13: =Datos!D13 | D13: 13 | E13: =IF(Datos!$G$13<=Bosque!$E$4,IF(Datos!$H$13<=Bosque!$E$5,Bosque!$M$6,Bosque!$M$7),IF(Datos!$G$13<=Bosque!$E$8,Bosque!$M$9,Bosque!$M$10)) | F13: =IF(Datos!$H$13<=Bosque!$E$11,IF(Datos!$E$13<=Bosque!$E$12,Bosque!$M$13,Bosque!$M$14),IF(Datos!$I$13<=Bosque!$E$15,Bosque!$M$16,Bosque!$M$17)) | G13: =IF(Datos!$E$13<=Bosque!$E$18,IF(Datos!$I$13<=Bosque!$E$19,Bosque!$M$20,Bosque!$M$21),Bosque!$M$22) | H13: =IF(Datos!$E$13<=Bosque!$E$23,IF(Datos!$E$13<=Bosque!$E$24,Bosque!$M$25,Bosque!$M$26),IF(Datos!$E$13<=Bosque!$E$27,Bosque!$M$28,Bosque!$M$29)) | I13: =IF(Datos!$G$13<=Bosque!$E$30,IF(Datos!$E$13<=Bosque!$E$31,Bosque!$M$32,Bosque!$M$33),IF(Datos!$E$13<=Bosque!$E$34,Bosque!$M$35,Bosque!$M$36)) | J13: =IF(Datos!$I$13<=Bosque!$E$37,IF(Datos!$H$13<=Bosque!$E$38,Bosque!$M$39,Bosque!$M$40),IF(Datos!$F$13<=Bosque!$E$41,Bosque!$M$42,Bosque!$M$43)) | K13: =IF(Datos!$G$13<=Bosque!$E$44,IF(Datos!$H$13<=Bosque!$E$45,Bosque!$M$46,Bosque!$M$47),IF(Datos!$F$13<=Bosque!$E$48,Bosque!$M$49,Bosque!$M$50)) | L13: =AVERAGE(E13:K13) | M13: =$M$2 | N13: =IF(L13>=M13,"Sí","No") | O13: =--AND(C13=1,N13="Sí") | P13: =--AND(C13=0,N13="Sí") | Q13: =--AND(C13=1,N13="No") | R13: =--AND(C13=0,N13="No") | S13: =--(C13=--(L13>=M13)) | T13: =O13*60000-P13*3000
A14: =Datos!A14 | B14: =Datos!B14 | C14: =Datos!D14 | D14: 14 | E14: =IF(Datos!$G$14<=Bosque!$E$4,IF(Datos!$H$14<=Bosque!$E$5,Bosque!$M$6,Bosque!$M$7),IF(Datos!$G$14<=Bosque!$E$8,Bosque!$M$9,Bosque!$M$10)) | F14: =IF(Datos!$H$14<=Bosque!$E$11,IF(Datos!$E$14<=Bosque!$E$12,Bosque!$M$13,Bosque!$M$14),IF(Datos!$I$14<=Bosque!$E$15,Bosque!$M$16,Bosque!$M$17)) | G14: =IF(Datos!$E$14<=Bosque!$E$18,IF(Datos!$I$14<=Bosque!$E$19,Bosque!$M$20,Bosque!$M$21),Bosque!$M$22) | H14: =IF(Datos!$E$14<=Bosque!$E$23,IF(Datos!$E$14<=Bosque!$E$24,Bosque!$M$25,Bosque!$M$26),IF(Datos!$E$14<=Bosque!$E$27,Bosque!$M$28,Bosque!$M$29)) | I14: =IF(Datos!$G$14<=Bosque!$E$30,IF(Datos!$E$14<=Bosque!$E$31,Bosque!$M$32,Bosque!$M$33),IF(Datos!$E$14<=Bosque!$E$34,Bosque!$M$35,Bosque!$M$36)) | J14: =IF(Datos!$I$14<=Bosque!$E$37,IF(Datos!$H$14<=Bosque!$E$38,Bosque!$M$39,Bosque!$M$40),IF(Datos!$F$14<=Bosque!$E$41,Bosque!$M$42,Bosque!$M$43)) | K14: =IF(Datos!$G$14<=Bosque!$E$44,IF(Datos!$H$14<=Bosque!$E$45,Bosque!$M$46,Bosque!$M$47),IF(Datos!$F$14<=Bosque!$E$48,Bosque!$M$49,Bosque!$M$50)) | L14: =AVERAGE(E14:K14) | M14: =$M$2 | N14: =IF(L14>=M14,"Sí","No") | O14: =--AND(C14=1,N14="Sí") | P14: =--AND(C14=0,N14="Sí") | Q14: =--AND(C14=1,N14="No") | R14: =--AND(C14=0,N14="No") | S14: =--(C14=--(L14>=M14)) | T14: =O14*60000-P14*3000
A15: =Datos!A15 | B15: =Datos!B15 | C15: =Datos!D15 | D15: 15 | E15: =IF(Datos!$G$15<=Bosque!$E$4,IF(Datos!$H$15<=Bosque!$E$5,Bosque!$M$6,Bosque!$M$7),IF(Datos!$G$15<=Bosque!$E$8,Bosque!$M$9,Bosque!$M$10)) | F15: =IF(Datos!$H$15<=Bosque!$E$11,IF(Datos!$E$15<=Bosque!$E$12,Bosque!$M$13,Bosque!$M$14),IF(Datos!$I$15<=Bosque!$E$15,Bosque!$M$16,Bosque!$M$17)) | G15: =IF(Datos!$E$15<=Bosque!$E$18,IF(Datos!$I$15<=Bosque!$E$19,Bosque!$M$20,Bosque!$M$21),Bosque!$M$22) | H15: =IF(Datos!$E$15<=Bosque!$E$23,IF(Datos!$E$15<=Bosque!$E$24,Bosque!$M$25,Bosque!$M$26),IF(Datos!$E$15<=Bosque!$E$27,Bosque!$M$28,Bosque!$M$29)) | I15: =IF(Datos!$G$15<=Bosque!$E$30,IF(Datos!$E$15<=Bosque!$E$31,Bosque!$M$32,Bosque!$M$33),IF(Datos!$E$15<=Bosque!$E$34,Bosque!$M$35,Bosque!$M$36)) | J15: =IF(Datos!$I$15<=Bosque!$E$37,IF(Datos!$H$15<=Bosque!$E$38,Bosque!$M$39,Bosque!$M$40),IF(Datos!$F$15<=Bosque!$E$41,Bosque!$M$42,Bosque!$M$43)) | K15: =IF(Datos!$G$15<=Bosque!$E$44,IF(Datos!$H$15<=Bosque!$E$45,Bosque!$M$46,Bosque!$M$47),IF(Datos!$F$15<=Bosque!$E$48,Bosque!$M$49,Bosque!$M$50)) | L15: =AVERAGE(E15:K15) | M15: =$M$2 | N15: =IF(L15>=M15,"Sí","No") | O15: =--AND(C15=1,N15="Sí") | P15: =--AND(C15=0,N15="Sí") | Q15: =--AND(C15=1,N15="No") | R15: =--AND(C15=0,N15="No") | S15: =--(C15=--(L15>=M15)) | T15: =O15*60000-P15*3000
A16: =Datos!A16 | B16: =Datos!B16 | C16: =Datos!D16 | D16: 16 | E16: =IF(Datos!$G$16<=Bosque!$E$4,IF(Datos!$H$16<=Bosque!$E$5,Bosque!$M$6,Bosque!$M$7),IF(Datos!$G$16<=Bosque!$E$8,Bosque!$M$9,Bosque!$M$10)) | F16: =IF(Datos!$H$16<=Bosque!$E$11,IF(Datos!$E$16<=Bosque!$E$12,Bosque!$M$13,Bosque!$M$14),IF(Datos!$I$16<=Bosque!$E$15,Bosque!$M$16,Bosque!$M$17)) | G16: =IF(Datos!$E$16<=Bosque!$E$18,IF(Datos!$I$16<=Bosque!$E$19,Bosque!$M$20,Bosque!$M$21),Bosque!$M$22) | H16: =IF(Datos!$E$16<=Bosque!$E$23,IF(Datos!$E$16<=Bosque!$E$24,Bosque!$M$25,Bosque!$M$26),IF(Datos!$E$16<=Bosque!$E$27,Bosque!$M$28,Bosque!$M$29)) | I16: =IF(Datos!$G$16<=Bosque!$E$30,IF(Datos!$E$16<=Bosque!$E$31,Bosque!$M$32,Bosque!$M$33),IF(Datos!$E$16<=Bosque!$E$34,Bosque!$M$35,Bosque!$M$36)) | J16: =IF(Datos!$I$16<=Bosque!$E$37,IF(Datos!$H$16<=Bosque!$E$38,Bosque!$M$39,Bosque!$M$40),IF(Datos!$F$16<=Bosque!$E$41,Bosque!$M$42,Bosque!$M$43)) | K16: =IF(Datos!$G$16<=Bosque!$E$44,IF(Datos!$H$16<=Bosque!$E$45,Bosque!$M$46,Bosque!$M$47),IF(Datos!$F$16<=Bosque!$E$48,Bosque!$M$49,Bosque!$M$50)) | L16: =AVERAGE(E16:K16) | M16: =$M$2 | N16: =IF(L16>=M16,"Sí","No") | O16: =--AND(C16=1,N16="Sí") | P16: =--AND(C16=0,N16="Sí") | Q16: =--AND(C16=1,N16="No") | R16: =--AND(C16=0,N16="No") | S16: =--(C16=--(L16>=M16)) | T16: =O16*60000-P16*3000
A17: =Datos!A17 | B17: =Datos!B17 | C17: =Datos!D17 | D17: 17 | E17: =IF(Datos!$G$17<=Bosque!$E$4,IF(Datos!$H$17<=Bosque!$E$5,Bosque!$M$6,Bosque!$M$7),IF(Datos!$G$17<=Bosque!$E$8,Bosque!$M$9,Bosque!$M$10)) | F17: =IF(Datos!$H$17<=Bosque!$E$11,IF(Datos!$E$17<=Bosque!$E$12,Bosque!$M$13,Bosque!$M$14),IF(Datos!$I$17<=Bosque!$E$15,Bosque!$M$16,Bosque!$M$17)) | G17: =IF(Datos!$E$17<=Bosque!$E$18,IF(Datos!$I$17<=Bosque!$E$19,Bosque!$M$20,Bosque!$M$21),Bosque!$M$22) | H17: =IF(Datos!$E$17<=Bosque!$E$23,IF(Datos!$E$17<=Bosque!$E$24,Bosque!$M$25,Bosque!$M$26),IF(Datos!$E$17<=Bosque!$E$27,Bosque!$M$28,Bosque!$M$29)) | I17: =IF(Datos!$G$17<=Bosque!$E$30,IF(Datos!$E$17<=Bosque!$E$31,Bosque!$M$32,Bosque!$M$33),IF(Datos!$E$17<=Bosque!$E$34,Bosque!$M$35,Bosque!$M$36)) | J17: =IF(Datos!$I$17<=Bosque!$E$37,IF(Datos!$H$17<=Bosque!$E$38,Bosque!$M$39,Bosque!$M$40),IF(Datos!$F$17<=Bosque!$E$41,Bosque!$M$42,Bosque!$M$43)) | K17: =IF(Datos!$G$17<=Bosque!$E$44,IF(Datos!$H$17<=Bosque!$E$45,Bosque!$M$46,Bosque!$M$47),IF(Datos!$F$17<=Bosque!$E$48,Bosque!$M$49,Bosque!$M$50)) | L17: =AVERAGE(E17:K17) | M17: =$M$2 | N17: =IF(L17>=M17,"Sí","No") | O17: =--AND(C17=1,N17="Sí") | P17: =--AND(C17=0,N17="Sí") | Q17: =--AND(C17=1,N17="No") | R17: =--AND(C17=0,N17="No") | S17: =--(C17=--(L17>=M17)) | T17: =O17*60000-P17*3000
A18: =Datos!A18 | B18: =Datos!B18 | C18: =Datos!D18 | D18: 18 | E18: =IF(Datos!$G$18<=Bosque!$E$4,IF(Datos!$H$18<=Bosque!$E$5,Bosque!$M$6,Bosque!$M$7),IF(Datos!$G$18<=Bosque!$E$8,Bosque!$M$9,Bosque!$M$10)) | F18: =IF(Datos!$H$18<=Bosque!$E$11,IF(Datos!$E$18<=Bosque!$E$12,Bosque!$M$13,Bosque!$M$14),IF(Datos!$I$18<=Bosque!$E$15,Bosque!$M$16,Bosque!$M$17)) | G18: =IF(Datos!$E$18<=Bosque!$E$18,IF(Datos!$I$18<=Bosque!$E$19,Bosque!$M$20,Bosque!$M$21),Bosque!$M$22) | H18: =IF(Datos!$E$18<=Bosque!$E$23,IF(Datos!$E$18<=Bosque!$E$24,Bosque!$M$25,Bosque!$M$26),IF(Datos!$E$18<=Bosque!$E$27,Bosque!$M$28,Bosque!$M$29)) | I18: =IF(Datos!$G$18<=Bosque!$E$30,IF(Datos!$E$18<=Bosque!$E$31,Bosque!$M$32,Bosque!$M$33),IF(Datos!$E$18<=Bosque!$E$34,Bosque!$M$35,Bosque!$M$36)) | J18: =IF(Datos!$I$18<=Bosque!$E$37,IF(Datos!$H$18<=Bosque!$E$38,Bosque!$M$39,Bosque!$M$40),IF(Datos!$F$18<=Bosque!$E$41,Bosque!$M$42,Bosque!$M$43)) | K18: =IF(Datos!$G$18<=Bosque!$E$44,IF(Datos!$H$18<=Bosque!$E$45,Bosque!$M$46,Bosque!$M$47),IF(Datos!$F$18<=Bosque!$E$48,Bosque!$M$49,Bosque!$M$50)) | L18: =AVERAGE(E18:K18) | M18: =$M$2 | N18: =IF(L18>=M18,"Sí","No") | O18: =--AND(C18=1,N18="Sí") | P18: =--AND(C18=0,N18="Sí") | Q18: =--AND(C18=1,N18="No") | R18: =--AND(C18=0,N18="No") | S18: =--(C18=--(L18>=M18)) | T18: =O18*60000-P18*3000
A19: =Datos!A19 | B19: =Datos!B19 | C19: =Datos!D19 | D19: 19 | E19: =IF(Datos!$G$19<=Bosque!$E$4,IF(Datos!$H$19<=Bosque!$E$5,Bosque!$M$6,Bosque!$M$7),IF(Datos!$G$19<=Bosque!$E$8,Bosque!$M$9,Bosque!$M$10)) | F19: =IF(Datos!$H$19<=Bosque!$E$11,IF(Datos!$E$19<=Bosque!$E$12,Bosque!$M$13,Bosque!$M$14),IF(Datos!$I$19<=Bosque!$E$15,Bosque!$M$16,Bosque!$M$17)) | G19: =IF(Datos!$E$19<=Bosque!$E$18,IF(Datos!$I$19<=Bosque!$E$19,Bosque!$M$20,Bosque!$M$21),Bosque!$M$22) | H19: =IF(Datos!$E$19<=Bosque!$E$23,IF(Datos!$E$19<=Bosque!$E$24,Bosque!$M$25,Bosque!$M$26),IF(Datos!$E$19<=Bosque!$E$27,Bosque!$M$28,Bosque!$M$29)) | I19: =IF(Datos!$G$19<=Bosque!$E$30,IF(Datos!$E$19<=Bosque!$E$31,Bosque!$M$32,Bosque!$M$33),IF(Datos!$E$19<=Bosque!$E$34,Bosque!$M$35,Bosque!$M$36)) | J19: =IF(Datos!$I$19<=Bosque!$E$37,IF(Datos!$H$19<=Bosque!$E$38,Bosque!$M$39,Bosque!$M$40),IF(Datos!$F$19<=Bosque!$E$41,Bosque!$M$42,Bosque!$M$43)) | K19: =IF(Datos!$G$19<=Bosque!$E$44,IF(Datos!$H$19<=Bosque!$E$45,Bosque!$M$46,Bosque!$M$47),IF(Datos!$F$19<=Bosque!$E$48,Bosque!$M$49,Bosque!$M$50)) | L19: =AVERAGE(E19:K19) | M19: =$M$2 | N19: =IF(L19>=M19,"Sí","No") | O19: =--AND(C19=1,N19="Sí") | P19: =--AND(C19=0,N19="Sí") | Q19: =--AND(C19=1,N19="No") | R19: =--AND(C19=0,N19="No") | S19: =--(C19=--(L19>=M19)) | T19: =O19*60000-P19*3000
A20: =Datos!A20 | B20: =Datos!B20 | C20: =Datos!D20 | D20: 20 | E20: =IF(Datos!$G$20<=Bosque!$E$4,IF(Datos!$H$20<=Bosque!$E$5,Bosque!$M$6,Bosque!$M$7),IF(Datos!$G$20<=Bosque!$E$8,Bosque!$M$9,Bosque!$M$10)) | F20: =IF(Datos!$H$20<=Bosque!$E$11,IF(Datos!$E$20<=Bosque!$E$12,Bosque!$M$13,Bosque!$M$14),IF(Datos!$I$20<=Bosque!$E$15,Bosque!$M$16,Bosque!$M$17)) | G20: =IF(Datos!$E$20<=Bosque!$E$18,IF(Datos!$I$20<=Bosque!$E$19,Bosque!$M$20,Bosque!$M$21),Bosque!$M$22) | H20: =IF(Datos!$E$20<=Bosque!$E$23,IF(Datos!$E$20<=Bosque!$E$24,Bosque!$M$25,Bosque!$M$26),IF(Datos!$E$20<=Bosque!$E$27,Bosque!$M$28,Bosque!$M$29)) | I20: =IF(Datos!$G$20<=Bosque!$E$30,IF(Datos!$E$20<=Bosque!$E$31,Bosque!$M$32,Bosque!$M$33),IF(Datos!$E$20<=Bosque!$E$34,Bosque!$M$35,Bosque!$M$36)) | J20: =IF(Datos!$I$20<=Bosque!$E$37,IF(Datos!$H$20<=Bosque!$E$38,Bosque!$M$39,Bosque!$M$40),IF(Datos!$F$20<=Bosque!$E$41,Bosque!$M$42,Bosque!$M$43)) | K20: =IF(Datos!$G$20<=Bosque!$E$44,IF(Datos!$H$20<=Bosque!$E$45,Bosque!$M$46,Bosque!$M$47),IF(Datos!$F$20<=Bosque!$E$48,Bosque!$M$49,Bosque!$M$50)) | L20: =AVERAGE(E20:K20) | M20: =$M$2 | N20: =IF(L20>=M20,"Sí","No") | O20: =--AND(C20=1,N20="Sí") | P20: =--AND(C20=0,N20="Sí") | Q20: =--AND(C20=1,N20="No") | R20: =--AND(C20=0,N20="No") | S20: =--(C20=--(L20>=M20)) | T20: =O20*60000-P20*3000
A21: =Datos!A21 | B21: =Datos!B21 | C21: =Datos!D21 | D21: 21 | E21: =IF(Datos!$G$21<=Bosque!$E$4,IF(Datos!$H$21<=Bosque!$E$5,Bosque!$M$6,Bosque!$M$7),IF(Datos!$G$21<=Bosque!$E$8,Bosque!$M$9,Bosque!$M$10)) | F21: =IF(Datos!$H$21<=Bosque!$E$11,IF(Datos!$E$21<=Bosque!$E$12,Bosque!$M$13,Bosque!$M$14),IF(Datos!$I$21<=Bosque!$E$15,Bosque!$M$16,Bosque!$M$17)) | G21: =IF(Datos!$E$21<=Bosque!$E$18,IF(Datos!$I$21<=Bosque!$E$19,Bosque!$M$20,Bosque!$M$21),Bosque!$M$22) | H21: =IF(Datos!$E$21<=Bosque!$E$23,IF(Datos!$E$21<=Bosque!$E$24,Bosque!$M$25,Bosque!$M$26),IF(Datos!$E$21<=Bosque!$E$27,Bosque!$M$28,Bosque!$M$29)) | I21: =IF(Datos!$G$21<=Bosque!$E$30,IF(Datos!$E$21<=Bosque!$E$31,Bosque!$M$32,Bosque!$M$33),IF(Datos!$E$21<=Bosque!$E$34,Bosque!$M$35,Bosque!$M$36)) | J21: =IF(Datos!$I$21<=Bosque!$E$37,IF(Datos!$H$21<=Bosque!$E$38,Bosque!$M$39,Bosque!$M$40),IF(Datos!$F$21<=Bosque!$E$41,Bosque!$M$42,Bosque!$M$43)) | K21: =IF(Datos!$G$21<=Bosque!$E$44,IF(Datos!$H$21<=Bosque!$E$45,Bosque!$M$46,Bosque!$M$47),IF(Datos!$F$21<=Bosque!$E$48,Bosque!$M$49,Bosque!$M$50)) | L21: =AVERAGE(E21:K21) | M21: =$M$2 | N21: =IF(L21>=M21,"Sí","No") | O21: =--AND(C21=1,N21="Sí") | P21: =--AND(C21=0,N21="Sí") | Q21: =--AND(C21=1,N21="No") | R21: =--AND(C21=0,N21="No") | S21: =--(C21=--(L21>=M21)) | T21: =O21*60000-P21*3000
A22: =Datos!A22 | B22: =Datos!B22 | C22: =Datos!D22 | D22: 22 | E22: =IF(Datos!$G$22<=Bosque!$E$4,IF(Datos!$H$22<=Bosque!$E$5,Bosque!$M$6,Bosque!$M$7),IF(Datos!$G$22<=Bosque!$E$8,Bosque!$M$9,Bosque!$M$10)) | F22: =IF(Datos!$H$22<=Bosque!$E$11,IF(Datos!$E$22<=Bosque!$E$12,Bosque!$M$13,Bosque!$M$14),IF(Datos!$I$22<=Bosque!$E$15,Bosque!$M$16,Bosque!$M$17)) | G22: =IF(Datos!$E$22<=Bosque!$E$18,IF(Datos!$I$22<=Bosque!$E$19,Bosque!$M$20,Bosque!$M$21),Bosque!$M$22) | H22: =IF(Datos!$E$22<=Bosque!$E$23,IF(Datos!$E$22<=Bosque!$E$24,Bosque!$M$25,Bosque!$M$26),IF(Datos!$E$22<=Bosque!$E$27,Bosque!$M$28,Bosque!$M$29)) | I22: =IF(Datos!$G$22<=Bosque!$E$30,IF(Datos!$E$22<=Bosque!$E$31,Bosque!$M$32,Bosque!$M$33),IF(Datos!$E$22<=Bosque!$E$34,Bosque!$M$35,Bosque!$M$36)) | J22: =IF(Datos!$I$22<=Bosque!$E$37,IF(Datos!$H$22<=Bosque!$E$38,Bosque!$M$39,Bosque!$M$40),IF(Datos!$F$22<=Bosque!$E$41,Bosque!$M$42,Bosque!$M$43)) | K22: =IF(Datos!$G$22<=Bosque!$E$44,IF(Datos!$H$22<=Bosque!$E$45,Bosque!$M$46,Bosque!$M$47),IF(Datos!$F$22<=Bosque!$E$48,Bosque!$M$49,Bosque!$M$50)) | L22: =AVERAGE(E22:K22) | M22: =$M$2 | N22: =IF(L22>=M22,"Sí","No") | O22: =--AND(C22=1,N22="Sí") | P22: =--AND(C22=0,N22="Sí") | Q22: =--AND(C22=1,N22="No") | R22: =--AND(C22=0,N22="No") | S22: =--(C22=--(L22>=M22)) | T22: =O22*60000-P22*3000
A23: =Datos!A23 | B23: =Datos!B23 | C23: =Datos!D23 | D23: 23 | E23: =IF(Datos!$G$23<=Bosque!$E$4,IF(Datos!$H$23<=Bosque!$E$5,Bosque!$M$6,Bosque!$M$7),IF(Datos!$G$23<=Bosque!$E$8,Bosque!$M$9,Bosque!$M$10)) | F23: =IF(Datos!$H$23<=Bosque!$E$11,IF(Datos!$E$23<=Bosque!$E$12,Bosque!$M$13,Bosque!$M$14),IF(Datos!$I$23<=Bosque!$E$15,Bosque!$M$16,Bosque!$M$17)) | G23: =IF(Datos!$E$23<=Bosque!$E$18,IF(Datos!$I$23<=Bosque!$E$19,Bosque!$M$20,Bosque!$M$21),Bosque!$M$22) | H23: =IF(Datos!$E$23<=Bosque!$E$23,IF(Datos!$E$23<=Bosque!$E$24,Bosque!$M$25,Bosque!$M$26),IF(Datos!$E$23<=Bosque!$E$27,Bosque!$M$28,Bosque!$M$29)) | I23: =IF(Datos!$G$23<=Bosque!$E$30,IF(Datos!$E$23<=Bosque!$E$31,Bosque!$M$32,Bosque!$M$33),IF(Datos!$E$23<=Bosque!$E$34,Bosque!$M$35,Bosque!$M$36)) | J23: =IF(Datos!$I$23<=Bosque!$E$37,IF(Datos!$H$23<=Bosque!$E$38,Bosque!$M$39,Bosque!$M$40),IF(Datos!$F$23<=Bosque!$E$41,Bosque!$M$42,Bosque!$M$43)) | K23: =IF(Datos!$G$23<=Bosque!$E$44,IF(Datos!$H$23<=Bosque!$E$45,Bosque!$M$46,Bosque!$M$47),IF(Datos!$F$23<=Bosque!$E$48,Bosque!$M$49,Bosque!$M$50)) | L23: =AVERAGE(E23:K23) | M23: =$M$2 | N23: =IF(L23>=M23,"Sí","No") | O23: =--AND(C23=1,N23="Sí") | P23: =--AND(C23=0,N23="Sí") | Q23: =--AND(C23=1,N23="No") | R23: =--AND(C23=0,N23="No") | S23: =--(C23=--(L23>=M23)) | T23: =O23*60000-P23*3000
A24: =Datos!A24 | B24: =Datos!B24 | C24: =Datos!D24 | D24: 24 | E24: =IF(Datos!$G$24<=Bosque!$E$4,IF(Datos!$H$24<=Bosque!$E$5,Bosque!$M$6,Bosque!$M$7),IF(Datos!$G$24<=Bosque!$E$8,Bosque!$M$9,Bosque!$M$10)) | F24: =IF(Datos!$H$24<=Bosque!$E$11,IF(Datos!$E$24<=Bosque!$E$12,Bosque!$M$13,Bosque!$M$14),IF(Datos!$I$24<=Bosque!$E$15,Bosque!$M$16,Bosque!$M$17)) | G24: =IF(Datos!$E$24<=Bosque!$E$18,IF(Datos!$I$24<=Bosque!$E$19,Bosque!$M$20,Bosque!$M$21),Bosque!$M$22) | H24: =IF(Datos!$E$24<=Bosque!$E$23,IF(Datos!$E$24<=Bosque!$E$24,Bosque!$M$25,Bosque!$M$26),IF(Datos!$E$24<=Bosque!$E$27,Bosque!$M$28,Bosque!$M$29)) | I24: =IF(Datos!$G$24<=Bosque!$E$30,IF(Datos!$E$24<=Bosque!$E$31,Bosque!$M$32,Bosque!$M$33),IF(Datos!$E$24<=Bosque!$E$34,Bosque!$M$35,Bosque!$M$36)) | J24: =IF(Datos!$I$24<=Bosque!$E$37,IF(Datos!$H$24<=Bosque!$E$38,Bosque!$M$39,Bosque!$M$40),IF(Datos!$F$24<=Bosque!$E$41,Bosque!$M$42,Bosque!$M$43)) | K24: =IF(Datos!$G$24<=Bosque!$E$44,IF(Datos!$H$24<=Bosque!$E$45,Bosque!$M$46,Bosque!$M$47),IF(Datos!$F$24<=Bosque!$E$48,Bosque!$M$49,Bosque!$M$50)) | L24: =AVERAGE(E24:K24) | M24: =$M$2 | N24: =IF(L24>=M24,"Sí","No") | O24: =--AND(C24=1,N24="Sí") | P24: =--AND(C24=0,N24="Sí") | Q24: =--AND(C24=1,N24="No") | R24: =--AND(C24=0,N24="No") | S24: =--(C24=--(L24>=M24)) | T24: =O24*60000-P24*3000
A25: =Datos!A25 | B25: =Datos!B25 | C25: =Datos!D25 | D25: 25 | E25: =IF(Datos!$G$25<=Bosque!$E$4,IF(Datos!$H$25<=Bosque!$E$5,Bosque!$M$6,Bosque!$M$7),IF(Datos!$G$25<=Bosque!$E$8,Bosque!$M$9,Bosque!$M$10)) | F25: =IF(Datos!$H$25<=Bosque!$E$11,IF(Datos!$E$25<=Bosque!$E$12,Bosque!$M$13,Bosque!$M$14),IF(Datos!$I$25<=Bosque!$E$15,Bosque!$M$16,Bosque!$M$17)) | G25: =IF(Datos!$E$25<=Bosque!$E$18,IF(Datos!$I$25<=Bosque!$E$19,Bosque!$M$20,Bosque!$M$21),Bosque!$M$22) | H25: =IF(Datos!$E$25<=Bosque!$E$23,IF(Datos!$E$25<=Bosque!$E$24,Bosque!$M$25,Bosque!$M$26),IF(Datos!$E$25<=Bosque!$E$27,Bosque!$M$28,Bosque!$M$29)) | I25: =IF(Datos!$G$25<=Bosque!$E$30,IF(Datos!$E$25<=Bosque!$E$31,Bosque!$M$32,Bosque!$M$33),IF(Datos!$E$25<=Bosque!$E$34,Bosque!$M$35,Bosque!$M$36)) | J25: =IF(Datos!$I$25<=Bosque!$E$37,IF(Datos!$H$25<=Bosque!$E$38,Bosque!$M$39,Bosque!$M$40),IF(Datos!$F$25<=Bosque!$E$41,Bosque!$M$42,Bosque!$M$43)) | K25: =IF(Datos!$G$25<=Bosque!$E$44,IF(Datos!$H$25<=Bosque!$E$45,Bosque!$M$46,Bosque!$M$47),IF(Datos!$F$25<=Bosque!$E$48,Bosque!$M$49,Bosque!$M$50)) | L25: =AVERAGE(E25:K25) | M25: =$M$2 | N25: =IF(L25>=M25,"Sí","No") | O25: =--AND(C25=1,N25="Sí") | P25: =--AND(C25=0,N25="Sí") | Q25: =--AND(C25=1,N25="No") | R25: =--AND(C25=0,N25="No") | S25: =--(C25=--(L25>=M25)) | T25: =O25*60000-P25*3000
A26: =Datos!A26 | B26: =Datos!B26 | C26: =Datos!D26 | D26: 26 | E26: =IF(Datos!$G$26<=Bosque!$E$4,IF(Datos!$H$26<=Bosque!$E$5,Bosque!$M$6,Bosque!$M$7),IF(Datos!$G$26<=Bosque!$E$8,Bosque!$M$9,Bosque!$M$10)) | F26: =IF(Datos!$H$26<=Bosque!$E$11,IF(Datos!$E$26<=Bosque!$E$12,Bosque!$M$13,Bosque!$M$14),IF(Datos!$I$26<=Bosque!$E$15,Bosque!$M$16,Bosque!$M$17)) | G26: =IF(Datos!$E$26<=Bosque!$E$18,IF(Datos!$I$26<=Bosque!$E$19,Bosque!$M$20,Bosque!$M$21),Bosque!$M$22) | H26: =IF(Datos!$E$26<=Bosque!$E$23,IF(Datos!$E$26<=Bosque!$E$24,Bosque!$M$25,Bosque!$M$26),IF(Datos!$E$26<=Bosque!$E$27,Bosque!$M$28,Bosque!$M$29)) | I26: =IF(Datos!$G$26<=Bosque!$E$30,IF(Datos!$E$26<=Bosque!$E$31,Bosque!$M$32,Bosque!$M$33),IF(Datos!$E$26<=Bosque!$E$34,Bosque!$M$35,Bosque!$M$36)) | J26: =IF(Datos!$I$26<=Bosque!$E$37,IF(Datos!$H$26<=Bosque!$E$38,Bosque!$M$39,Bosque!$M$40),IF(Datos!$F$26<=Bosque!$E$41,Bosque!$M$42,Bosque!$M$43)) | K26: =IF(Datos!$G$26<=Bosque!$E$44,IF(Datos!$H$26<=Bosque!$E$45,Bosque!$M$46,Bosque!$M$47),IF(Datos!$F$26<=Bosque!$E$48,Bosque!$M$49,Bosque!$M$50)) | L26: =AVERAGE(E26:K26) | M26: =$M$2 | N26: =IF(L26>=M26,"Sí","No") | O26: =--AND(C26=1,N26="Sí") | P26: =--AND(C26=0,N26="Sí") | Q26: =--AND(C26=1,N26="No") | R26: =--AND(C26=0,N26="No") | S26: =--(C26=--(L26>=M26)) | T26: =O26*60000-P26*3000
A27: =Datos!A27 | B27: =Datos!B27 | C27: =Datos!D27 | D27: 27 | E27: =IF(Datos!$G$27<=Bosque!$E$4,IF(Datos!$H$27<=Bosque!$E$5,Bosque!$M$6,Bosque!$M$7),IF(Datos!$G$27<=Bosque!$E$8,Bosque!$M$9,Bosque!$M$10)) | F27: =IF(Datos!$H$27<=Bosque!$E$11,IF(Datos!$E$27<=Bosque!$E$12,Bosque!$M$13,Bosque!$M$14),IF(Datos!$I$27<=Bosque!$E$15,Bosque!$M$16,Bosque!$M$17)) | G27: =IF(Datos!$E$27<=Bosque!$E$18,IF(Datos!$I$27<=Bosque!$E$19,Bosque!$M$20,Bosque!$M$21),Bosque!$M$22) | H27: =IF(Datos!$E$27<=Bosque!$E$23,IF(Datos!$E$27<=Bosque!$E$24,Bosque!$M$25,Bosque!$M$26),IF(Datos!$E$27<=Bosque!$E$27,Bosque!$M$28,Bosque!$M$29)) | I27: =IF(Datos!$G$27<=Bosque!$E$30,IF(Datos!$E$27<=Bosque!$E$31,Bosque!$M$32,Bosque!$M$33),IF(Datos!$E$27<=Bosque!$E$34,Bosque!$M$35,Bosque!$M$36)) | J27: =IF(Datos!$I$27<=Bosque!$E$37,IF(Datos!$H$27<=Bosque!$E$38,Bosque!$M$39,Bosque!$M$40),IF(Datos!$F$27<=Bosque!$E$41,Bosque!$M$42,Bosque!$M$43)) | K27: =IF(Datos!$G$27<=Bosque!$E$44,IF(Datos!$H$27<=Bosque!$E$45,Bosque!$M$46,Bosque!$M$47),IF(Datos!$F$27<=Bosque!$E$48,Bosque!$M$49,Bosque!$M$50)) | L27: =AVERAGE(E27:K27) | M27: =$M$2 | N27: =IF(L27>=M27,"Sí","No") | O27: =--AND(C27=1,N27="Sí") | P27: =--AND(C27=0,N27="Sí") | Q27: =--AND(C27=1,N27="No") | R27: =--AND(C27=0,N27="No") | S27: =--(C27=--(L27>=M27)) | T27: =O27*60000-P27*3000
A28: =Datos!A28 | B28: =Datos!B28 | C28: =Datos!D28 | D28: 28 | E28: =IF(Datos!$G$28<=Bosque!$E$4,IF(Datos!$H$28<=Bosque!$E$5,Bosque!$M$6,Bosque!$M$7),IF(Datos!$G$28<=Bosque!$E$8,Bosque!$M$9,Bosque!$M$10)) | F28: =IF(Datos!$H$28<=Bosque!$E$11,IF(Datos!$E$28<=Bosque!$E$12,Bosque!$M$13,Bosque!$M$14),IF(Datos!$I$28<=Bosque!$E$15,Bosque!$M$16,Bosque!$M$17)) | G28: =IF(Datos!$E$28<=Bosque!$E$18,IF(Datos!$I$28<=Bosque!$E$19,Bosque!$M$20,Bosque!$M$21),Bosque!$M$22) | H28: =IF(Datos!$E$28<=Bosque!$E$23,IF(Datos!$E$28<=Bosque!$E$24,Bosque!$M$25,Bosque!$M$26),IF(Datos!$E$28<=Bosque!$E$27,Bosque!$M$28,Bosque!$M$29)) | I28: =IF(Datos!$G$28<=Bosque!$E$30,IF(Datos!$E$28<=Bosque!$E$31,Bosque!$M$32,Bosque!$M$33),IF(Datos!$E$28<=Bosque!$E$34,Bosque!$M$35,Bosque!$M$36)) | J28: =IF(Datos!$I$28<=Bosque!$E$37,IF(Datos!$H$28<=Bosque!$E$38,Bosque!$M$39,Bosque!$M$40),IF(Datos!$F$28<=Bosque!$E$41,Bosque!$M$42,Bosque!$M$43)) | K28: =IF(Datos!$G$28<=Bosque!$E$44,IF(Datos!$H$28<=Bosque!$E$45,Bosque!$M$46,Bosque!$M$47),IF(Datos!$F$28<=Bosque!$E$48,Bosque!$M$49,Bosque!$M$50)) | L28: =AVERAGE(E28:K28) | M28: =$M$2 | N28: =IF(L28>=M28,"Sí","No") | O28: =--AND(C28=1,N28="Sí") | P28: =--AND(C28=0,N28="Sí") | Q28: =--AND(C28=1,N28="No") | R28: =--AND(C28=0,N28="No") | S28: =--(C28=--(L28>=M28)) | T28: =O28*60000-P28*3000
A29: =Datos!A29 | B29: =Datos!B29 | C29: =Datos!D29 | D29: 29 | E29: =IF(Datos!$G$29<=Bosque!$E$4,IF(Datos!$H$29<=Bosque!$E$5,Bosque!$M$6,Bosque!$M$7),IF(Datos!$G$29<=Bosque!$E$8,Bosque!$M$9,Bosque!$M$10)) | F29: =IF(Datos!$H$29<=Bosque!$E$11,IF(Datos!$E$29<=Bosque!$E$12,Bosque!$M$13,Bosque!$M$14),IF(Datos!$I$29<=Bosque!$E$15,Bosque!$M$16,Bosque!$M$17)) | G29: =IF(Datos!$E$29<=Bosque!$E$18,IF(Datos!$I$29<=Bosque!$E$19,Bosque!$M$20,Bosque!$M$21),Bosque!$M$22) | H29: =IF(Datos!$E$29<=Bosque!$E$23,IF(Datos!$E$29<=Bosque!$E$24,Bosque!$M$25,Bosque!$M$26),IF(Datos!$E$29<=Bosque!$E$27,Bosque!$M$28,Bosque!$M$29)) | I29: =IF(Datos!$G$29<=Bosque!$E$30,IF(Datos!$E$29<=Bosque!$E$31,Bosque!$M$32,Bosque!$M$33),IF(Datos!$E$29<=Bosque!$E$34,Bosque!$M$35,Bosque!$M$36)) | J29: =IF(Datos!$I$29<=Bosque!$E$37,IF(Datos!$H$29<=Bosque!$E$38,Bosque!$M$39,Bosque!$M$40),IF(Datos!$F$29<=Bosque!$E$41,Bosque!$M$42,Bosque!$M$43)) | K29: =IF(Datos!$G$29<=Bosque!$E$44,IF(Datos!$H$29<=Bosque!$E$45,Bosque!$M$46,Bosque!$M$47),IF(Datos!$F$29<=Bosque!$E$48,Bosque!$M$49,Bosque!$M$50)) | L29: =AVERAGE(E29:K29) | M29: =$M$2 | N29: =IF(L29>=M29,"Sí","No") | O29: =--AND(C29=1,N29="Sí") | P29: =--AND(C29=0,N29="Sí") | Q29: =--AND(C29=1,N29="No") | R29: =--AND(C29=0,N29="No") | S29: =--(C29=--(L29>=M29)) | T29: =O29*60000-P29*3000
A30: =Datos!A30 | B30: =Datos!B30 | C30: =Datos!D30 | D30: 30 | E30: =IF(Datos!$G$30<=Bosque!$E$4,IF(Datos!$H$30<=Bosque!$E$5,Bosque!$M$6,Bosque!$M$7),IF(Datos!$G$30<=Bosque!$E$8,Bosque!$M$9,Bosque!$M$10)) | F30: =IF(Datos!$H$30<=Bosque!$E$11,IF(Datos!$E$30<=Bosque!$E$12,Bosque!$M$13,Bosque!$M$14),IF(Datos!$I$30<=Bosque!$E$15,Bosque!$M$16,Bosque!$M$17)) | G30: =IF(Datos!$E$30<=Bosque!$E$18,IF(Datos!$I$30<=Bosque!$E$19,Bosque!$M$20,Bosque!$M$21),Bosque!$M$22) | H30: =IF(Datos!$E$30<=Bosque!$E$23,IF(Datos!$E$30<=Bosque!$E$24,Bosque!$M$25,Bosque!$M$26),IF(Datos!$E$30<=Bosque!$E$27,Bosque!$M$28,Bosque!$M$29)) | I30: =IF(Datos!$G$30<=Bosque!$E$30,IF(Datos!$E$30<=Bosque!$E$31,Bosque!$M$32,Bosque!$M$33),IF(Datos!$E$30<=Bosque!$E$34,Bosque!$M$35,Bosque!$M$36)) | J30: =IF(Datos!$I$30<=Bosque!$E$37,IF(Datos!$H$30<=Bosque!$E$38,Bosque!$M$39,Bosque!$M$40),IF(Datos!$F$30<=Bosque!$E$41,Bosque!$M$42,Bosque!$M$43)) | K30: =IF(Datos!$G$30<=Bosque!$E$44,IF(Datos!$H$30<=Bosque!$E$45,Bosque!$M$46,Bosque!$M$47),IF(Datos!$F$30<=Bosque!$E$48,Bosque!$M$49,Bosque!$M$50)) | L30: =AVERAGE(E30:K30) | M30: =$M$2 | N30: =IF(L30>=M30,"Sí","No") | O30: =--AND(C30=1,N30="Sí") | P30: =--AND(C30=0,N30="Sí") | Q30: =--AND(C30=1,N30="No") | R30: =--AND(C30=0,N30="No") | S30: =--(C30=--(L30>=M30)) | T30: =O30*60000-P30*3000
A31: =Datos!A31 | B31: =Datos!B31 | C31: =Datos!D31 | D31: 31 | E31: =IF(Datos!$G$31<=Bosque!$E$4,IF(Datos!$H$31<=Bosque!$E$5,Bosque!$M$6,Bosque!$M$7),IF(Datos!$G$31<=Bosque!$E$8,Bosque!$M$9,Bosque!$M$10)) | F31: =IF(Datos!$H$31<=Bosque!$E$11,IF(Datos!$E$31<=Bosque!$E$12,Bosque!$M$13,Bosque!$M$14),IF(Datos!$I$31<=Bosque!$E$15,Bosque!$M$16,Bosque!$M$17)) | G31: =IF(Datos!$E$31<=Bosque!$E$18,IF(Datos!$I$31<=Bosque!$E$19,Bosque!$M$20,Bosque!$M$21),Bosque!$M$22) | H31: =IF(Datos!$E$31<=Bosque!$E$23,IF(Datos!$E$31<=Bosque!$E$24,Bosque!$M$25,Bosque!$M$26),IF(Datos!$E$31<=Bosque!$E$27,Bosque!$M$28,Bosque!$M$29)) | I31: =IF(Datos!$G$31<=Bosque!$E$30,IF(Datos!$E$31<=Bosque!$E$31,Bosque!$M$32,Bosque!$M$33),IF(Datos!$E$31<=Bosque!$E$34,Bosque!$M$35,Bosque!$M$36)) | J31: =IF(Datos!$I$31<=Bosque!$E$37,IF(Datos!$H$31<=Bosque!$E$38,Bosque!$M$39,Bosque!$M$40),IF(Datos!$F$31<=Bosque!$E$41,Bosque!$M$42,Bosque!$M$43)) | K31: =IF(Datos!$G$31<=Bosque!$E$44,IF(Datos!$H$31<=Bosque!$E$45,Bosque!$M$46,Bosque!$M$47),IF(Datos!$F$31<=Bosque!$E$48,Bosque!$M$49,Bosque!$M$50)) | L31: =AVERAGE(E31:K31) | M31: =$M$2 | N31: =IF(L31>=M31,"Sí","No") | O31: =--AND(C31=1,N31="Sí") | P31: =--AND(C31=0,N31="Sí") | Q31: =--AND(C31=1,N31="No") | R31: =--AND(C31=0,N31="No") | S31: =--(C31=--(L31>=M31)) | T31: =O31*60000-P31*3000
A32: =Datos!A32 | B32: =Datos!B32 | C32: =Datos!D32 | D32: 32 | E32: =IF(Datos!$G$32<=Bosque!$E$4,IF(Datos!$H$32<=Bosque!$E$5,Bosque!$M$6,Bosque!$M$7),IF(Datos!$G$32<=Bosque!$E$8,Bosque!$M$9,Bosque!$M$10)) | F32: =IF(Datos!$H$32<=Bosque!$E$11,IF(Datos!$E$32<=Bosque!$E$12,Bosque!$M$13,Bosque!$M$14),IF(Datos!$I$32<=Bosque!$E$15,Bosque!$M$16,Bosque!$M$17)) | G32: =IF(Datos!$E$32<=Bosque!$E$18,IF(Datos!$I$32<=Bosque!$E$19,Bosque!$M$20,Bosque!$M$21),Bosque!$M$22) | H32: =IF(Datos!$E$32<=Bosque!$E$23,IF(Datos!$E$32<=Bosque!$E$24,Bosque!$M$25,Bosque!$M$26),IF(Datos!$E$32<=Bosque!$E$27,Bosque!$M$28,Bosque!$M$29)) | I32: =IF(Datos!$G$32<=Bosque!$E$30,IF(Datos!$E$32<=Bosque!$E$31,Bosque!$M$32,Bosque!$M$33),IF(Datos!$E$32<=Bosque!$E$34,Bosque!$M$35,Bosque!$M$36)) | J32: =IF(Datos!$I$32<=Bosque!$E$37,IF(Datos!$H$32<=Bosque!$E$38,Bosque!$M$39,Bosque!$M$40),IF(Datos!$F$32<=Bosque!$E$41,Bosque!$M$42,Bosque!$M$43)) | K32: =IF(Datos!$G$32<=Bosque!$E$44,IF(Datos!$H$32<=Bosque!$E$45,Bosque!$M$46,Bosque!$M$47),IF(Datos!$F$32<=Bosque!$E$48,Bosque!$M$49,Bosque!$M$50)) | L32: =AVERAGE(E32:K32) | M32: =$M$2 | N32: =IF(L32>=M32,"Sí","No") | O32: =--AND(C32=1,N32="Sí") | P32: =--AND(C32=0,N32="Sí") | Q32: =--AND(C32=1,N32="No") | R32: =--AND(C32=0,N32="No") | S32: =--(C32=--(L32>=M32)) | T32: =O32*60000-P32*3000
A33: =Datos!A33 | B33: =Datos!B33 | C33: =Datos!D33 | D33: 33 | E33: =IF(Datos!$G$33<=Bosque!$E$4,IF(Datos!$H$33<=Bosque!$E$5,Bosque!$M$6,Bosque!$M$7),IF(Datos!$G$33<=Bosque!$E$8,Bosque!$M$9,Bosque!$M$10)) | F33: =IF(Datos!$H$33<=Bosque!$E$11,IF(Datos!$E$33<=Bosque!$E$12,Bosque!$M$13,Bosque!$M$14),IF(Datos!$I$33<=Bosque!$E$15,Bosque!$M$16,Bosque!$M$17)) | G33: =IF(Datos!$E$33<=Bosque!$E$18,IF(Datos!$I$33<=Bosque!$E$19,Bosque!$M$20,Bosque!$M$21),Bosque!$M$22) | H33: =IF(Datos!$E$33<=Bosque!$E$23,IF(Datos!$E$33<=Bosque!$E$24,Bosque!$M$25,Bosque!$M$26),IF(Datos!$E$33<=Bosque!$E$27,Bosque!$M$28,Bosque!$M$29)) | I33: =IF(Datos!$G$33<=Bosque!$E$30,IF(Datos!$E$33<=Bosque!$E$31,Bosque!$M$32,Bosque!$M$33),IF(Datos!$E$33<=Bosque!$E$34,Bosque!$M$35,Bosque!$M$36)) | J33: =IF(Datos!$I$33<=Bosque!$E$37,IF(Datos!$H$33<=Bosque!$E$38,Bosque!$M$39,Bosque!$M$40),IF(Datos!$F$33<=Bosque!$E$41,Bosque!$M$42,Bosque!$M$43)) | K33: =IF(Datos!$G$33<=Bosque!$E$44,IF(Datos!$H$33<=Bosque!$E$45,Bosque!$M$46,Bosque!$M$47),IF(Datos!$F$33<=Bosque!$E$48,Bosque!$M$49,Bosque!$M$50)) | L33: =AVERAGE(E33:K33) | M33: =$M$2 | N33: =IF(L33>=M33,"Sí","No") | O33: =--AND(C33=1,N33="Sí") | P33: =--AND(C33=0,N33="Sí") | Q33: =--AND(C33=1,N33="No") | R33: =--AND(C33=0,N33="No") | S33: =--(C33=--(L33>=M33)) | T33: =O33*60000-P33*3000
A34: =Datos!A34 | B34: =Datos!B34 | C34: =Datos!D34 | D34: 34 | E34: =IF(Datos!$G$34<=Bosque!$E$4,IF(Datos!$H$34<=Bosque!$E$5,Bosque!$M$6,Bosque!$M$7),IF(Datos!$G$34<=Bosque!$E$8,Bosque!$M$9,Bosque!$M$10)) | F34: =IF(Datos!$H$34<=Bosque!$E$11,IF(Datos!$E$34<=Bosque!$E$12,Bosque!$M$13,Bosque!$M$14),IF(Datos!$I$34<=Bosque!$E$15,Bosque!$M$16,Bosque!$M$17)) | G34: =IF(Datos!$E$34<=Bosque!$E$18,IF(Datos!$I$34<=Bosque!$E$19,Bosque!$M$20,Bosque!$M$21),Bosque!$M$22) | H34: =IF(Datos!$E$34<=Bosque!$E$23,IF(Datos!$E$34<=Bosque!$E$24,Bosque!$M$25,Bosque!$M$26),IF(Datos!$E$34<=Bosque!$E$27,Bosque!$M$28,Bosque!$M$29)) | I34: =IF(Datos!$G$34<=Bosque!$E$30,IF(Datos!$E$34<=Bosque!$E$31,Bosque!$M$32,Bosque!$M$33),IF(Datos!$E$34<=Bosque!$E$34,Bosque!$M$35,Bosque!$M$36)) | J34: =IF(Datos!$I$34<=Bosque!$E$37,IF(Datos!$H$34<=Bosque!$E$38,Bosque!$M$39,Bosque!$M$40),IF(Datos!$F$34<=Bosque!$E$41,Bosque!$M$42,Bosque!$M$43)) | K34: =IF(Datos!$G$34<=Bosque!$E$44,IF(Datos!$H$34<=Bosque!$E$45,Bosque!$M$46,Bosque!$M$47),IF(Datos!$F$34<=Bosque!$E$48,Bosque!$M$49,Bosque!$M$50)) | L34: =AVERAGE(E34:K34) | M34: =$M$2 | N34: =IF(L34>=M34,"Sí","No") | O34: =--AND(C34=1,N34="Sí") | P34: =--AND(C34=0,N34="Sí") | Q34: =--AND(C34=1,N34="No") | R34: =--AND(C34=0,N34="No") | S34: =--(C34=--(L34>=M34)) | T34: =O34*60000-P34*3000
A35: =Datos!A35 | B35: =Datos!B35 | C35: =Datos!D35 | D35: 35 | E35: =IF(Datos!$G$35<=Bosque!$E$4,IF(Datos!$H$35<=Bosque!$E$5,Bosque!$M$6,Bosque!$M$7),IF(Datos!$G$35<=Bosque!$E$8,Bosque!$M$9,Bosque!$M$10)) | F35: =IF(Datos!$H$35<=Bosque!$E$11,IF(Datos!$E$35<=Bosque!$E$12,Bosque!$M$13,Bosque!$M$14),IF(Datos!$I$35<=Bosque!$E$15,Bosque!$M$16,Bosque!$M$17)) | G35: =IF(Datos!$E$35<=Bosque!$E$18,IF(Datos!$I$35<=Bosque!$E$19,Bosque!$M$20,Bosque!$M$21),Bosque!$M$22) | H35: =IF(Datos!$E$35<=Bosque!$E$23,IF(Datos!$E$35<=Bosque!$E$24,Bosque!$M$25,Bosque!$M$26),IF(Datos!$E$35<=Bosque!$E$27,Bosque!$M$28,Bosque!$M$29)) | I35: =IF(Datos!$G$35<=Bosque!$E$30,IF(Datos!$E$35<=Bosque!$E$31,Bosque!$M$32,Bosque!$M$33),IF(Datos!$E$35<=Bosque!$E$34,Bosque!$M$35,Bosque!$M$36)) | J35: =IF(Datos!$I$35<=Bosque!$E$37,IF(Datos!$H$35<=Bosque!$E$38,Bosque!$M$39,Bosque!$M$40),IF(Datos!$F$35<=Bosque!$E$41,Bosque!$M$42,Bosque!$M$43)) | K35: =IF(Datos!$G$35<=Bosque!$E$44,IF(Datos!$H$35<=Bosque!$E$45,Bosque!$M$46,Bosque!$M$47),IF(Datos!$F$35<=Bosque!$E$48,Bosque!$M$49,Bosque!$M$50)) | L35: =AVERAGE(E35:K35) | M35: =$M$2 | N35: =IF(L35>=M35,"Sí","No") | O35: =--AND(C35=1,N35="Sí") | P35: =--AND(C35=0,N35="Sí") | Q35: =--AND(C35=1,N35="No") | R35: =--AND(C35=0,N35="No") | S35: =--(C35=--(L35>=M35)) | T35: =O35*60000-P35*3000
A36: =Datos!A36 | B36: =Datos!B36 | C36: =Datos!D36 | D36: 36 | E36: =IF(Datos!$G$36<=Bosque!$E$4,IF(Datos!$H$36<=Bosque!$E$5,Bosque!$M$6,Bosque!$M$7),IF(Datos!$G$36<=Bosque!$E$8,Bosque!$M$9,Bosque!$M$10)) | F36: =IF(Datos!$H$36<=Bosque!$E$11,IF(Datos!$E$36<=Bosque!$E$12,Bosque!$M$13,Bosque!$M$14),IF(Datos!$I$36<=Bosque!$E$15,Bosque!$M$16,Bosque!$M$17)) | G36: =IF(Datos!$E$36<=Bosque!$E$18,IF(Datos!$I$36<=Bosque!$E$19,Bosque!$M$20,Bosque!$M$21),Bosque!$M$22) | H36: =IF(Datos!$E$36<=Bosque!$E$23,IF(Datos!$E$36<=Bosque!$E$24,Bosque!$M$25,Bosque!$M$26),IF(Datos!$E$36<=Bosque!$E$27,Bosque!$M$28,Bosque!$M$29)) | I36: =IF(Datos!$G$36<=Bosque!$E$30,IF(Datos!$E$36<=Bosque!$E$31,Bosque!$M$32,Bosque!$M$33),IF(Datos!$E$36<=Bosque!$E$34,Bosque!$M$35,Bosque!$M$36)) | J36: =IF(Datos!$I$36<=Bosque!$E$37,IF(Datos!$H$36<=Bosque!$E$38,Bosque!$M$39,Bosque!$M$40),IF(Datos!$F$36<=Bosque!$E$41,Bosque!$M$42,Bosque!$M$43)) | K36: =IF(Datos!$G$36<=Bosque!$E$44,IF(Datos!$H$36<=Bosque!$E$45,Bosque!$M$46,Bosque!$M$47),IF(Datos!$F$36<=Bosque!$E$48,Bosque!$M$49,Bosque!$M$50)) | L36: =AVERAGE(E36:K36) | M36: =$M$2 | N36: =IF(L36>=M36,"Sí","No") | O36: =--AND(C36=1,N36="Sí") | P36: =--AND(C36=0,N36="Sí") | Q36: =--AND(C36=1,N36="No") | R36: =--AND(C36=0,N36="No") | S36: =--(C36=--(L36>=M36)) | T36: =O36*60000-P36*3000
A37: =Datos!A37 | B37: =Datos!B37 | C37: =Datos!D37 | D37: 37 | E37: =IF(Datos!$G$37<=Bosque!$E$4,IF(Datos!$H$37<=Bosque!$E$5,Bosque!$M$6,Bosque!$M$7),IF(Datos!$G$37<=Bosque!$E$8,Bosque!$M$9,Bosque!$M$10)) | F37: =IF(Datos!$H$37<=Bosque!$E$11,IF(Datos!$E$37<=Bosque!$E$12,Bosque!$M$13,Bosque!$M$14),IF(Datos!$I$37<=Bosque!$E$15,Bosque!$M$16,Bosque!$M$17)) | G37: =IF(Datos!$E$37<=Bosque!$E$18,IF(Datos!$I$37<=Bosque!$E$19,Bosque!$M$20,Bosque!$M$21),Bosque!$M$22) | H37: =IF(Datos!$E$37<=Bosque!$E$23,IF(Datos!$E$37<=Bosque!$E$24,Bosque!$M$25,Bosque!$M$26),IF(Datos!$E$37<=Bosque!$E$27,Bosque!$M$28,Bosque!$M$29)) | I37: =IF(Datos!$G$37<=Bosque!$E$30,IF(Datos!$E$37<=Bosque!$E$31,Bosque!$M$32,Bosque!$M$33),IF(Datos!$E$37<=Bosque!$E$34,Bosque!$M$35,Bosque!$M$36)) | J37: =IF(Datos!$I$37<=Bosque!$E$37,IF(Datos!$H$37<=Bosque!$E$38,Bosque!$M$39,Bosque!$M$40),IF(Datos!$F$37<=Bosque!$E$41,Bosque!$M$42,Bosque!$M$43)) | K37: =IF(Datos!$G$37<=Bosque!$E$44,IF(Datos!$H$37<=Bosque!$E$45,Bosque!$M$46,Bosque!$M$47),IF(Datos!$F$37<=Bosque!$E$48,Bosque!$M$49,Bosque!$M$50)) | L37: =AVERAGE(E37:K37) | M37: =$M$2 | N37: =IF(L37>=M37,"Sí","No") | O37: =--AND(C37=1,N37="Sí") | P37: =--AND(C37=0,N37="Sí") | Q37: =--AND(C37=1,N37="No") | R37: =--AND(C37=0,N37="No") | S37: =--(C37=--(L37>=M37)) | T37: =O37*60000-P37*3000
A38: =Datos!A38 | B38: =Datos!B38 | C38: =Datos!D38 | D38: 38 | E38: =IF(Datos!$G$38<=Bosque!$E$4,IF(Datos!$H$38<=Bosque!$E$5,Bosque!$M$6,Bosque!$M$7),IF(Datos!$G$38<=Bosque!$E$8,Bosque!$M$9,Bosque!$M$10)) | F38: =IF(Datos!$H$38<=Bosque!$E$11,IF(Datos!$E$38<=Bosque!$E$12,Bosque!$M$13,Bosque!$M$14),IF(Datos!$I$38<=Bosque!$E$15,Bosque!$M$16,Bosque!$M$17)) | G38: =IF(Datos!$E$38<=Bosque!$E$18,IF(Datos!$I$38<=Bosque!$E$19,Bosque!$M$20,Bosque!$M$21),Bosque!$M$22) | H38: =IF(Datos!$E$38<=Bosque!$E$23,IF(Datos!$E$38<=Bosque!$E$24,Bosque!$M$25,Bosque!$M$26),IF(Datos!$E$38<=Bosque!$E$27,Bosque!$M$28,Bosque!$M$29)) | I38: =IF(Datos!$G$38<=Bosque!$E$30,IF(Datos!$E$38<=Bosque!$E$31,Bosque!$M$32,Bosque!$M$33),IF(Datos!$E$38<=Bosque!$E$34,Bosque!$M$35,Bosque!$M$36)) | J38: =IF(Datos!$I$38<=Bosque!$E$37,IF(Datos!$H$38<=Bosque!$E$38,Bosque!$M$39,Bosque!$M$40),IF(Datos!$F$38<=Bosque!$E$41,Bosque!$M$42,Bosque!$M$43)) | K38: =IF(Datos!$G$38<=Bosque!$E$44,IF(Datos!$H$38<=Bosque!$E$45,Bosque!$M$46,Bosque!$M$47),IF(Datos!$F$38<=Bosque!$E$48,Bosque!$M$49,Bosque!$M$50)) | L38: =AVERAGE(E38:K38) | M38: =$M$2 | N38: =IF(L38>=M38,"Sí","No") | O38: =--AND(C38=1,N38="Sí") | P38: =--AND(C38=0,N38="Sí") | Q38: =--AND(C38=1,N38="No") | R38: =--AND(C38=0,N38="No") | S38: =--(C38=--(L38>=M38)) | T38: =O38*60000-P38*3000
A39: =Datos!A39 | B39: =Datos!B39 | C39: =Datos!D39 | D39: 39 | E39: =IF(Datos!$G$39<=Bosque!$E$4,IF(Datos!$H$39<=Bosque!$E$5,Bosque!$M$6,Bosque!$M$7),IF(Datos!$G$39<=Bosque!$E$8,Bosque!$M$9,Bosque!$M$10)) | F39: =IF(Datos!$H$39<=Bosque!$E$11,IF(Datos!$E$39<=Bosque!$E$12,Bosque!$M$13,Bosque!$M$14),IF(Datos!$I$39<=Bosque!$E$15,Bosque!$M$16,Bosque!$M$17)) | G39: =IF(Datos!$E$39<=Bosque!$E$18,IF(Datos!$I$39<=Bosque!$E$19,Bosque!$M$20,Bosque!$M$21),Bosque!$M$22) | H39: =IF(Datos!$E$39<=Bosque!$E$23,IF(Datos!$E$39<=Bosque!$E$24,Bosque!$M$25,Bosque!$M$26),IF(Datos!$E$39<=Bosque!$E$27,Bosque!$M$28,Bosque!$M$29)) | I39: =IF(Datos!$G$39<=Bosque!$E$30,IF(Datos!$E$39<=Bosque!$E$31,Bosque!$M$32,Bosque!$M$33),IF(Datos!$E$39<=Bosque!$E$34,Bosque!$M$35,Bosque!$M$36)) | J39: =IF(Datos!$I$39<=Bosque!$E$37,IF(Datos!$H$39<=Bosque!$E$38,Bosque!$M$39,Bosque!$M$40),IF(Datos!$F$39<=Bosque!$E$41,Bosque!$M$42,Bosque!$M$43)) | K39: =IF(Datos!$G$39<=Bosque!$E$44,IF(Datos!$H$39<=Bosque!$E$45,Bosque!$M$46,Bosque!$M$47),IF(Datos!$F$39<=Bosque!$E$48,Bosque!$M$49,Bosque!$M$50)) | L39: =AVERAGE(E39:K39) | M39: =$M$2 | N39: =IF(L39>=M39,"Sí","No") | O39: =--AND(C39=1,N39="Sí") | P39: =--AND(C39=0,N39="Sí") | Q39: =--AND(C39=1,N39="No") | R39: =--AND(C39=0,N39="No") | S39: =--(C39=--(L39>=M39)) | T39: =O39*60000-P39*3000
